Workbook

Sheet Inputs
A1: Spell Scoring Probability Model Inputs
A3: Parameter | B3: Value | C3: Meaning | D3: Editable?
A4: Ranks per energy | B4: 15 | C4: Ranks are 1–15; no wraparound | D4: Yes
A5: Deck 1 energies | B5: 4 | C5: Deck 1 = 4×15 = 60 cards, no wilds | D5: Yes
A6: Deck 2 energies | B6: 5 | C6: Deck 2 = 5×15 = 75 cards, no wilds | D6: Yes
A7: Raw weight alpha | B7: 0.8 | C7: Combined model weight on raw final-state rarity | D7: Yes
A8: Marginal weight | B8: =1-B7 -> 0.2 | C8: Weight on incremental build-path probability | D8: Formula
A9: Opportunity cards (m) | B9: 15 | C9: Fixed-opportunity window; default 15 so the full 3–15 scoring table is comparable | D9: Yes
A11: Model notes
A12: Raw model: counts valid exact n-card final subsets and divides by all n-card subsets: valid_count / COMBIN(total_cards,n).
A13: Marginal model: starts with the raw probability of a valid 3-card spell, then multiplies by realistic conditional extension probabilities from size k to k+1.
A14: Combined model: log-space blend. Combined probability = EXP(-(alpha×raw_difficulty + (1-alpha)×marginal_difficulty)).
A15: Difficulty is always -LN(probability). No integer rounding or score scaling is applied in this workbook.
A17: Fixed-opportunity model: expected valid size-n spell opportunities inside an m-card window. Uses valid_count × COMBIN(total_cards-n,m-n) / COMBIN(total_cards,m).
A18: Bounded P≥1 estimate: 1 - EXP(-expected opportunities). This gives a comparable probability-like value for -LN difficulty.
A19: Combined fixed model: log-space blend. Combined difficulty = alpha×fixed-opportunity difficulty + (1-alpha)×marginal-build difficulty.
A20: Use Final_Fixed_Tables for current comparisons. Final_Tables preserves the older exact-size raw model for reference.

Sheet Raw_Model
A1: Deck | B1: Energies E | C1: Size n | D1: Total cards N | E1: All n-card subsets | F1: Conj count | G1: Conj prob | H1: Trans count | I1: Trans prob | J1: PT count | K1: PT prob | L1: Ench count | M1: Ench prob | N1: Conj diff | O1: Trans diff | P1: PT diff | Q1: Ench diff
A2: 1 | B2: =Inputs!$B$5 -> 4 | C2: 3 | D2: =B2*Inputs!$B$4 -> 60 | E2: =COMBIN(D2,C2) -> 34220 | F2: =B2*COMBIN(Inputs!$B$4,C2) -> 1820 | G2: =F2/E2 -> 0.053185272 | H2: =(Inputs!$B$4-C2+1)*POWER(B2,C2) -> 832 | I2: =H2/E2 -> 0.024313267 | J2: =B2*(Inputs!$B$4-C2+1) -> 52 | K2: =J2/E2 -> 0.0015195792 | L2: =IF(C2<=B2,Inputs!$B$4*COMBIN(B2,C2),"") -> 60 | M2: =IF(L2="","",L2/E2) -> 0.0017533606 | N2: =-LN(G2) -> 2.9339738 | O2: =-LN(I2) -> 3.7167331 | P2: =-LN(K2) -> 6.4893218 | Q2: =IF(M2="","",-LN(M2)) -> 6.346221
A3: 1 | B3: =Inputs!$B$5 -> 4 | C3: 4 | D3: =B3*Inputs!$B$4 -> 60 | E3: =COMBIN(D3,C3) -> 487635 | F3: =B3*COMBIN(Inputs!$B$4,C3) -> 5460 | G3: =F3/E3 -> 0.011196899 | H3: =(Inputs!$B$4-C3+1)*POWER(B3,C3) -> 3072 | I3: =H3/E3 -> 0.0062997939 | J3: =B3*(Inputs!$B$4-C3+1) -> 48 | K3: =J3/E3 -> 9.843428e-05 | L3: =IF(C3<=B3,Inputs!$B$4*COMBIN(B3,C3),"") -> 15 | M3: =IF(L3="","",L3/E3) -> 3.0760712e-05 | N3: =-LN(G3) -> 4.4921184 | O3: =-LN(I3) -> 5.0672384 | P3: =-LN(K3) -> 9.2261214 | Q3: =IF(M3="","",-LN(M3)) -> 10.389272
A4: 1 | B4: =Inputs!$B$5 -> 4 | C4: 5 | D4: =B4*Inputs!$B$4 -> 60 | E4: =COMBIN(D4,C4) -> 5461512 | F4: =B4*COMBIN(Inputs!$B$4,C4) -> 12012 | G4: =F4/E4 -> 0.0021993909 | H4: =(Inputs!$B$4-C4+1)*POWER(B4,C4) -> 11264 | I4: =H4/E4 -> 0.0020624325 | J4: =B4*(Inputs!$B$4-C4+1) -> 44 | K4: =J4/E4 -> 8.0563771e-06 | L4: =IF(C4<=B4,Inputs!$B$4*COMBIN(B4,C4),"") | M4: =IF(L4="","",L4/E4) | N4: =-LN(G4) -> 6.1195748 | O4: =-LN(I4) -> 6.1838692 | P4: =-LN(K4) -> 11.729047 | Q4: =IF(M4="","",-LN(M4))
A5: 1 | B5: =Inputs!$B$5 -> 4 | C5: 6 | D5: =B5*Inputs!$B$4 -> 60 | E5: =COMBIN(D5,C5) -> 50063860 | F5: =B5*COMBIN(Inputs!$B$4,C5) -> 20020 | G5: =F5/E5 -> 0.00039988926 | H5: =(Inputs!$B$4-C5+1)*POWER(B5,C5) -> 40960 | I5: =H5/E5 -> 0.00081815505 | J5: =B5*(Inputs!$B$4-C5+1) -> 40 | K5: =J5/E5 -> 7.9897954e-07 | L5: =IF(C5<=B5,Inputs!$B$4*COMBIN(B5,C5),"") | M5: =IF(L5="","",L5/E5) | N5: =-LN(G5) -> 7.8243229 | O5: =-LN(I5) -> 7.1084587 | P5: =-LN(K5) -> 14.03993 | Q5: =IF(M5="","",-LN(M5))
A6: 1 | B6: =Inputs!$B$5 -> 4 | C6: 7 | D6: =B6*Inputs!$B$4 -> 60 | E6: =COMBIN(D6,C6) -> 3.8620692e+08 | F6: =B6*COMBIN(Inputs!$B$4,C6) -> 25740 | G6: =F6/E6 -> 6.664821e-05 | H6: =(Inputs!$B$4-C6+1)*POWER(B6,C6) -> 147456 | I6: =H6/E6 -> 0.00038180569 | J6: =B6*(Inputs!$B$4-C6+1) -> 36 | K6: =J6/E6 -> 9.321428e-08 | L6: =IF(C6<=B6,Inputs!$B$4*COMBIN(B6,C6),"") | M6: =IF(L6="","",L6/E6) | N6: =-LN(G6) -> 9.6160824 | O6: =-LN(I6) -> 7.8705987 | P6: =-LN(K6) -> 16.188365 | Q6: =IF(M6="","",-LN(M6))
A7: 1 | B7: =Inputs!$B$5 -> 4 | C7: 8 | D7: =B7*Inputs!$B$4 -> 60 | E7: =COMBIN(D7,C7) -> 2.5586208e+09 | F7: =B7*COMBIN(Inputs!$B$4,C7) -> 25740 | G7: =F7/E7 -> 1.0060107e-05 | H7: =(Inputs!$B$4-C7+1)*POWER(B7,C7) -> 524288 | I7: =H7/E7 -> 0.00020491039 | J7: =B7*(Inputs!$B$4-C7+1) -> 32 | K7: =J7/E7 -> 1.2506738e-08 | L7: =IF(C7<=B7,Inputs!$B$4*COMBIN(B7,C7),"") | M7: =IF(L7="","",L7/E7) | N7: =-LN(G7) -> 11.506933 | O7: =-LN(I7) -> 8.4929378 | P7: =-LN(K7) -> 18.196998 | Q7: =IF(M7="","",-LN(M7))
A8: 1 | B8: =Inputs!$B$5 -> 4 | C8: 9 | D8: =B8*Inputs!$B$4 -> 60 | E8: =COMBIN(D8,C8) -> 1.4783143e+10 | F8: =B8*COMBIN(Inputs!$B$4,C8) -> 20020 | G8: =F8/E8 -> 1.3542452e-06 | H8: =(Inputs!$B$4-C8+1)*POWER(B8,C8) -> 1835008 | I8: =H8/E8 -> 0.00012412841 | J8: =B8*(Inputs!$B$4-C8+1) -> 28 | K8: =J8/E8 -> 1.8940492e-09 | L8: =IF(C8<=B8,Inputs!$B$4*COMBIN(B8,C8),"") | M8: =IF(L8="","",L8/E8) | N8: =-LN(G8) -> 13.512266 | O8: =-LN(I8) -> 8.994194 | P8: =-LN(K8) -> 20.084549 | Q8: =IF(M8="","",-LN(M8))
A9: 1 | B9: =Inputs!$B$5 -> 4 | C9: 10 | D9: =B9*Inputs!$B$4 -> 60 | E9: =COMBIN(D9,C9) -> 75394027566 | F9: =B9*COMBIN(Inputs!$B$4,C9) -> 12012 | G9: =F9/E9 -> 1.5932296e-07 | H9: =(Inputs!$B$4-C9+1)*POWER(B9,C9) -> 6291456 | I9: =H9/E9 -> 8.3447671e-05 | J9: =B9*(Inputs!$B$4-C9+1) -> 24 | K9: =J9/E9 -> 3.183276e-10 | L9: =IF(C9<=B9,Inputs!$B$4*COMBIN(B9,C9),"") | M9: =IF(L9="","",L9/E9) | N9: =-LN(G9) -> 15.652332 | O9: =-LN(I9) -> 9.3912908 | P9: =-LN(K9) -> 21.86794 | Q9: =IF(M9="","",-LN(M9))
A10: 1 | B10: =Inputs!$B$5 -> 4 | C10: 11 | D10: =B10*Inputs!$B$4 -> 60 | E10: =COMBIN(D10,C10) -> 342700125300 | F10: =B10*COMBIN(Inputs!$B$4,C10) -> 5460 | G10: =F10/E10 -> 1.5932296e-08 | H10: =(Inputs!$B$4-C10+1)*POWER(B10,C10) -> 20971520 | I10: =H10/E10 -> 6.1194959e-05 | J10: =B10*(Inputs!$B$4-C10+1) -> 20 | K10: =J10/E10 -> 5.836006e-11 | L10: =IF(C10<=B10,Inputs!$B$4*COMBIN(B10,C10),"") | M10: =IF(L10="","",L10/E10) | N10: =-LN(G10) -> 17.954918 | O10: =-LN(I10) -> 9.7014457 | P10: =-LN(K10) -> 23.564389 | Q10: =IF(M10="","",-LN(M10))
A11: 1 | B11: =Inputs!$B$5 -> 4 | C11: 12 | D11: =B11*Inputs!$B$4 -> 60 | E11: =COMBIN(D11,C11) -> 1.3993588e+12 | F11: =B11*COMBIN(Inputs!$B$4,C11) -> 1820 | G11: =F11/E11 -> 1.3005956e-09 | H11: =(Inputs!$B$4-C11+1)*POWER(B11,C11) -> 67108864 | I11: =H11/E11 -> 4.7956866e-05 | J11: =B11*(Inputs!$B$4-C11+1) -> 16 | K11: =J11/E11 -> 1.1433808e-11 | L11: =IF(C11<=B11,Inputs!$B$4*COMBIN(B11,C11),"") | M11: =IF(L11="","",L11/E11) | N11: =-LN(G11) -> 20.460443 | O11: =-LN(I11) -> 9.9452086 | P11: =-LN(K11) -> 25.194447 | Q11: =IF(M11="","",-LN(M11))
A12: 1 | B12: =Inputs!$B$5 -> 4 | C12: 13 | D12: =B12*Inputs!$B$4 -> 60 | E12: =COMBIN(D12,C12) -> 5.1668634e+12 | F12: =B12*COMBIN(Inputs!$B$4,C12) -> 420 | G12: =F12/E12 -> 8.1287227e-11 | H12: =(Inputs!$B$4-C12+1)*POWER(B12,C12) -> 201326592 | I12: =H12/E12 -> 3.8964953e-05 | J12: =B12*(Inputs!$B$4-C12+1) -> 12 | K12: =J12/E12 -> 2.3224922e-12 | L12: =IF(C12<=B12,Inputs!$B$4*COMBIN(B12,C12),"") | M12: =IF(L12="","",L12/E12) | N12: =-LN(G12) -> 23.233032 | O12: =-LN(I12) -> 10.152848 | P12: =-LN(K12) -> 26.78838 | Q12: =IF(M12="","",-LN(M12))
A13: 1 | B13: =Inputs!$B$5 -> 4 | C13: 14 | D13: =B13*Inputs!$B$4 -> 60 | E13: =COMBIN(D13,C13) -> 17345898649800 | F13: =B13*COMBIN(Inputs!$B$4,C13) -> 60 | G13: =F13/E13 -> 3.4590309e-12 | H13: =(Inputs!$B$4-C13+1)*POWER(B13,C13) -> 536870912 | I13: =H13/E13 -> 3.0950885e-05 | J13: =B13*(Inputs!$B$4-C13+1) -> 8 | K13: =J13/E13 -> 4.6120412e-13 | L13: =IF(C13<=B13,Inputs!$B$4*COMBIN(B13,C13),"") | M13: =IF(L13="","",L13/E13) | N13: =-LN(G13) -> 26.390033 | O13: =-LN(I13) -> 10.383109 | P13: =-LN(K13) -> 28.404936 | Q13: =IF(M13="","",-LN(M13))
A14: 1 | B14: =Inputs!$B$5 -> 4 | C14: 15 | D14: =B14*Inputs!$B$4 -> 60 | E14: =COMBIN(D14,C14) -> 5.3194089e+13 | F14: =B14*COMBIN(Inputs!$B$4,C14) -> 4 | G14: =F14/E14 -> 7.5196325e-14 | H14: =(Inputs!$B$4-C14+1)*POWER(B14,C14) -> 1073741824 | I14: =H14/E14 -> 2.018536e-05 | J14: =B14*(Inputs!$B$4-C14+1) -> 4 | K14: =J14/E14 -> 7.5196325e-14 | L14: =IF(C14<=B14,Inputs!$B$4*COMBIN(B14,C14),"") | M14: =IF(L14="","",L14/E14) | N14: =-LN(G14) -> 30.218674 | O14: =-LN(I14) -> 10.810553 | P14: =-LN(K14) -> 30.218674 | Q14: =IF(M14="","",-LN(M14))
A15: 2 | B15: =Inputs!$B$6 -> 5 | C15: 3 | D15: =B15*Inputs!$B$4 -> 75 | E15: =COMBIN(D15,C15) -> 67525 | F15: =B15*COMBIN(Inputs!$B$4,C15) -> 2275 | G15: =F15/E15 -> 0.033691225 | H15: =(Inputs!$B$4-C15+1)*POWER(B15,C15) -> 1625 | I15: =H15/E15 -> 0.024065161 | J15: =B15*(Inputs!$B$4-C15+1) -> 65 | K15: =J15/E15 -> 0.00096260644 | L15: =IF(C15<=B15,Inputs!$B$4*COMBIN(B15,C15),"") -> 150 | M15: =IF(L15="","",L15/E15) -> 0.0022213995 | N15: =-LN(G15) -> 3.3905178 | O15: =-LN(I15) -> 3.7269901 | P15: =-LN(K15) -> 6.9458659 | Q15: =IF(M15="","",-LN(M15)) -> 6.1096179
A16: 2 | B16: =Inputs!$B$6 -> 5 | C16: 4 | D16: =B16*Inputs!$B$4 -> 75 | E16: =COMBIN(D16,C16) -> 1215450 | F16: =B16*COMBIN(Inputs!$B$4,C16) -> 6825 | G16: =F16/E16 -> 0.0056152042 | H16: =(Inputs!$B$4-C16+1)*POWER(B16,C16) -> 7500 | I16: =H16/E16 -> 0.0061705541 | J16: =B16*(Inputs!$B$4-C16+1) -> 60 | K16: =J16/E16 -> 4.9364433e-05 | L16: =IF(C16<=B16,Inputs!$B$4*COMBIN(B16,C16),"") -> 75 | M16: =IF(L16="","",L16/E16) -> 6.1705541e-05 | N16: =-LN(G16) -> 5.1822773 | O16: =-LN(I16) -> 5.0879666 | P16: =-LN(K16) -> 9.9162804 | Q16: =IF(M16="","",-LN(M16)) -> 9.6931368
A17: 2 | B17: =Inputs!$B$6 -> 5 | C17: 5 | D17: =B17*Inputs!$B$4 -> 75 | E17: =COMBIN(D17,C17) -> 17259390 | F17: =B17*COMBIN(Inputs!$B$4,C17) -> 15015 | G17: =F17/E17 -> 0.00086996122 | H17: =(Inputs!$B$4-C17+1)*POWER(B17,C17) -> 34375 | I17: =H17/E17 -> 0.0019916695 | J17: =B17*(Inputs!$B$4-C17+1) -> 55 | K17: =J17/E17 -> 3.1866711e-06 | L17: =IF(C17<=B17,Inputs!$B$4*COMBIN(B17,C17),"") -> 15 | M17: =IF(L17="","",L17/E17) -> 8.6909213e-07 | N17: =-LN(G17) -> 7.0470619 | O17: =-LN(I17) -> 6.2187821 | P17: =-LN(K17) -> 12.656534 | Q17: =IF(M17="","",-LN(M17)) -> 13.955817
A18: 2 | B18: =Inputs!$B$6 -> 5 | C18: 6 | D18: =B18*Inputs!$B$4 -> 75 | E18: =COMBIN(D18,C18) -> 201359550 | F18: =B18*COMBIN(Inputs!$B$4,C18) -> 25025 | G18: =F18/E18 -> 0.00012428017 | H18: =(Inputs!$B$4-C18+1)*POWER(B18,C18) -> 156250 | I18: =H18/E18 -> 0.00077597512 | J18: =B18*(Inputs!$B$4-C18+1) -> 50 | K18: =J18/E18 -> 2.4831204e-07 | L18: =IF(C18<=B18,Inputs!$B$4*COMBIN(B18,C18),"") | M18: =IF(L18="","",L18/E18) | N18: =-LN(G18) -> 8.9929721 | O18: =-LN(I18) -> 7.1613901 | P18: =-LN(K18) -> 15.20858 | Q18: =IF(M18="","",-LN(M18))
A19: 2 | B19: =Inputs!$B$6 -> 5 | C19: 7 | D19: =B19*Inputs!$B$4 -> 75 | E19: =COMBIN(D19,C19) -> 1984829850 | F19: =B19*COMBIN(Inputs!$B$4,C19) -> 32175 | G19: =F19/E19 -> 1.6210458e-05 | H19: =(Inputs!$B$4-C19+1)*POWER(B19,C19) -> 703125 | I19: =H19/E19 -> 0.00035424951 | J19: =B19*(Inputs!$B$4-C19+1) -> 45 | K19: =J19/E19 -> 2.2671969e-08 | L19: =IF(C19<=B19,Inputs!$B$4*COMBIN(B19,C19),"") | M19: =IF(L19="","",L19/E19) | N19: =-LN(G19) -> 11.029854 | O19: =-LN(I19) -> 7.9455091 | P19: =-LN(K19) -> 17.602137 | Q19: =IF(M19="","",-LN(M19))
A20: 2 | B20: =Inputs!$B$6 -> 5 | C20: 8 | D20: =B20*Inputs!$B$4 -> 75 | E20: =COMBIN(D20,C20) -> 16871053725 | F20: =B20*COMBIN(Inputs!$B$4,C20) -> 32175 | G20: =F20/E20 -> 1.9071127e-06 | H20: =(Inputs!$B$4-C20+1)*POWER(B20,C20) -> 3125000 | I20: =H20/E20 -> 0.0001852285 | J20: =B20*(Inputs!$B$4-C20+1) -> 40 | K20: =J20/E20 -> 2.3709248e-09 | L20: =IF(C20<=B20,Inputs!$B$4*COMBIN(B20,C20),"") | M20: =IF(L20="","",L20/E20) | N20: =-LN(G20) -> 13.16992 | O20: =-LN(I20) -> 8.5939204 | P20: =-LN(K20) -> 19.859986 | Q20: =IF(M20="","",-LN(M20))
A21: 2 | B21: =Inputs!$B$6 -> 5 | C21: 9 | D21: =B21*Inputs!$B$4 -> 75 | E21: =COMBIN(D21,C21) -> 125595622175 | F21: =B21*COMBIN(Inputs!$B$4,C21) -> 25025 | G21: =F21/E21 -> 1.9925058e-07 | H21: =(Inputs!$B$4-C21+1)*POWER(B21,C21) -> 13671875 | I21: =H21/E21 -> 0.0001088563 | J21: =B21*(Inputs!$B$4-C21+1) -> 35 | K21: =J21/E21 -> 2.7867213e-10 | L21: =IF(C21<=B21,Inputs!$B$4*COMBIN(B21,C21),"") | M21: =IF(L21="","",L21/E21) | N21: =-LN(G21) -> 15.428703 | O21: =-LN(I21) -> 9.1254819 | P21: =-LN(K21) -> 22.000985 | Q21: =IF(M21="","",-LN(M21))
A22: 2 | B22: =Inputs!$B$6 -> 5 | C22: 10 | D22: =B22*Inputs!$B$4 -> 75 | E22: =COMBIN(D22,C22) -> 828931106355 | F22: =B22*COMBIN(Inputs!$B$4,C22) -> 15015 | G22: =F22/E22 -> 1.8113689e-08 | H22: =(Inputs!$B$4-C22+1)*POWER(B22,C22) -> 58593750 | I22: =H22/E22 -> 7.0685911e-05 | J22: =B22*(Inputs!$B$4-C22+1) -> 30 | K22: =J22/E22 -> 3.6191186e-11 | L22: =IF(C22<=B22,Inputs!$B$4*COMBIN(B22,C22),"") | M22: =IF(L22="","",L22/E22) | N22: =-LN(G22) -> 17.826598 | O22: =-LN(I22) -> 9.5572643 | P22: =-LN(K22) -> 24.042206 | Q22: =IF(M22="","",-LN(M22))
A23: 2 | B23: =Inputs!$B$6 -> 5 | C23: 11 | D23: =B23*Inputs!$B$4 -> 75 | E23: =COMBIN(D23,C23) -> 4898229264825 | F23: =B23*COMBIN(Inputs!$B$4,C23) -> 6825 | G23: =F23/E23 -> 1.3933607e-09 | H23: =(Inputs!$B$4-C23+1)*POWER(B23,C23) -> 244140625 | I23: =H23/E23 -> 4.9842629e-05 | J23: =B23*(Inputs!$B$4-C23+1) -> 25 | K23: =J23/E23 -> 5.1038852e-12 | L23: =IF(C23<=B23,Inputs!$B$4*COMBIN(B23,C23),"") | M23: =IF(L23="","",L23/E23) | N23: =-LN(G23) -> 20.391547 | O23: =-LN(I23) -> 9.9066399 | P23: =-LN(K23) -> 26.001019 | Q23: =IF(M23="","",-LN(M23))
A24: 2 | B24: =Inputs!$B$6 -> 5 | C24: 12 | D24: =B24*Inputs!$B$4 -> 75 | E24: =COMBIN(D24,C24) -> 2.6123889e+13 | F24: =B24*COMBIN(Inputs!$B$4,C24) -> 2275 | G24: =F24/E24 -> 8.7085042e-11 | H24: =(Inputs!$B$4-C24+1)*POWER(B24,C24) -> 976562500 | I24: =H24/E24 -> 3.7381972e-05 | J24: =B24*(Inputs!$B$4-C24+1) -> 20 | K24: =J24/E24 -> 7.6558278e-13 | L24: =IF(C24<=B24,Inputs!$B$4*COMBIN(B24,C24),"") | M24: =IF(L24="","",L24/E24) | N24: =-LN(G24) -> 23.164136 | O24: =-LN(I24) -> 10.194322 | P24: =-LN(K24) -> 27.898139 | Q24: =IF(M24="","",-LN(M24))
A25: 2 | B25: =Inputs!$B$6 -> 5 | C25: 13 | D25: =B25*Inputs!$B$4 -> 75 | E25: =COMBIN(D25,C25) -> 1.2660039e+14 | F25: =B25*COMBIN(Inputs!$B$4,C25) -> 525 | G25: =F25/E25 -> 4.1469067e-12 | H25: =(Inputs!$B$4-C25+1)*POWER(B25,C25) -> 3662109375 | I25: =H25/E25 -> 2.8926526e-05 | J25: =B25*(Inputs!$B$4-C25+1) -> 15 | K25: =J25/E25 -> 1.1848305e-13 | L25: =IF(C25<=B25,Inputs!$B$4*COMBIN(B25,C25),"") | M25: =IF(L25="","",L25/E25) | N25: =-LN(G25) -> 26.208658 | O25: =-LN(I25) -> 10.450752 | P25: =-LN(K25) -> 29.764006 | Q25: =IF(M25="","",-LN(M25))
A26: 2 | B26: =Inputs!$B$6 -> 5 | C26: 14 | D26: =B26*Inputs!$B$4 -> 75 | E26: =COMBIN(D26,C26) -> 560658857389200 | F26: =B26*COMBIN(Inputs!$B$4,C26) -> 75 | G26: =F26/E26 -> 1.3377119e-13 | H26: =(Inputs!$B$4-C26+1)*POWER(B26,C26) -> 12207031250 | I26: =H26/E26 -> 2.1772654e-05 | J26: =B26*(Inputs!$B$4-C26+1) -> 10 | K26: =J26/E26 -> 1.7836158e-14 | L26: =IF(C26<=B26,Inputs!$B$4*COMBIN(B26,C26),"") | M26: =IF(L26="","",L26/E26) | N26: =-LN(G26) -> 29.642646 | O26: =-LN(I26) -> 10.734856 | P26: =-LN(K26) -> 31.657549 | Q26: =IF(M26="","",-LN(M26))
A27: 2 | B27: =Inputs!$B$6 -> 5 | C27: 15 | D27: =B27*Inputs!$B$4 -> 75 | E27: =COMBIN(D27,C27) -> 2.2800127e+15 | F27: =B27*COMBIN(Inputs!$B$4,C27) -> 5 | G27: =F27/E27 -> 2.1929703e-15 | H27: =(Inputs!$B$4-C27+1)*POWER(B27,C27) -> 30517578125 | I27: =H27/E27 -> 1.3384828e-05 | J27: =B27*(Inputs!$B$4-C27+1) -> 5 | K27: =J27/E27 -> 2.1929703e-15 | L27: =IF(C27<=B27,Inputs!$B$4*COMBIN(B27,C27),"") | M27: =IF(L27="","",L27/E27) | N27: =-LN(G27) -> 33.753519 | O27: =-LN(I27) -> 11.221389 | P27: =-LN(K27) -> 33.753519 | Q27: =IF(M27="","",-LN(M27))

Sheet Marginal_Model
A1: Deck | B1: Energies E | C1: Final size n | D1: Total cards N | E1: Prev size k | F1: Ext prob C | G1: Ext prob T | H1: Ext prob PT | I1: Ext prob Ench | J1: Build prob C | K1: Build prob T | L1: Build prob PT | M1: Build prob Ench | N1: Build diff C | O1: Build diff T | P1: Build diff PT | Q1: Build diff Ench
A2: 1 | B2: =Inputs!$B$5 -> 4 | C2: 3 | D2: =B2*Inputs!$B$4 -> 60 | E2: =IF(C2=3,"",C2-1) | F2: =IF(C2=3,1,(Inputs!$B$4-(C2-1))/(D2-(C2-1))) -> 1 | G2: =IF(C2=3,1,((MAX(Inputs!$B$4-(C2-1)-1,0)*2*B2)+(2*B2))/((Inputs!$B$4-(C2-1)+1)*(D2-(C2-1)))) -> 1 | H2: =IF(C2=3,1,((MAX(Inputs!$B$4-(C2-1)-1,0)*2)+(2))/((Inputs!$B$4-(C2-1)+1)*(D2-(C2-1)))) -> 1 | I2: =IF(C2=3,1,IF((C2-1)<B2,(B2-(C2-1))/(D2-(C2-1)),"")) -> 1 | J2: =IF(C2=3,B2*COMBIN(Inputs!$B$4,3)/COMBIN(D2,3),J1*F2) -> 0.053185272 | K2: =IF(C2=3,(Inputs!$B$4-3+1)*POWER(B2,3)/COMBIN(D2,3),K1*G2) -> 0.024313267 | L2: =IF(C2=3,B2*(Inputs!$B$4-3+1)/COMBIN(D2,3),L1*H2) -> 0.0015195792 | M2: =IF(C2=3,IF(3<=B2,Inputs!$B$4*COMBIN(B2,3)/COMBIN(D2,3),""),IF(I2="","",M1*I2)) -> 0.0017533606 | N2: =-LN(J2) -> 2.9339738 | O2: =-LN(K2) -> 3.7167331 | P2: =-LN(L2) -> 6.4893218 | Q2: =IF(M2="","",-LN(M2)) -> 6.346221
A3: 1 | B3: =Inputs!$B$5 -> 4 | C3: 4 | D3: =B3*Inputs!$B$4 -> 60 | E3: =IF(C3=3,"",C3-1) -> 3 | F3: =IF(C3=3,1,(Inputs!$B$4-(C3-1))/(D3-(C3-1))) -> 0.21052632 | G3: =IF(C3=3,1,((MAX(Inputs!$B$4-(C3-1)-1,0)*2*B3)+(2*B3))/((Inputs!$B$4-(C3-1)+1)*(D3-(C3-1)))) -> 0.12955466 | H3: =IF(C3=3,1,((MAX(Inputs!$B$4-(C3-1)-1,0)*2)+(2))/((Inputs!$B$4-(C3-1)+1)*(D3-(C3-1)))) -> 0.032388664 | I3: =IF(C3=3,1,IF((C3-1)<B3,(B3-(C3-1))/(D3-(C3-1)),"")) -> 0.01754386 | J3: =IF(C3=3,B3*COMBIN(Inputs!$B$4,3)/COMBIN(D3,3),J2*F3) -> 0.011196899 | K3: =IF(C3=3,(Inputs!$B$4-3+1)*POWER(B3,3)/COMBIN(D3,3),K2*G3) -> 0.003149897 | L3: =IF(C3=3,B3*(Inputs!$B$4-3+1)/COMBIN(D3,3),L2*H3) -> 4.921714e-05 | M3: =IF(C3=3,IF(3<=B3,Inputs!$B$4*COMBIN(B3,3)/COMBIN(D3,3),""),IF(I3="","",M2*I3)) -> 3.0760712e-05 | N3: =-LN(J3) -> 4.4921184 | O3: =-LN(K3) -> 5.7603855 | P3: =-LN(L3) -> 9.9192686 | Q3: =IF(M3="","",-LN(M3)) -> 10.389272
A4: 1 | B4: =Inputs!$B$5 -> 4 | C4: 5 | D4: =B4*Inputs!$B$4 -> 60 | E4: =IF(C4=3,"",C4-1) -> 4 | F4: =IF(C4=3,1,(Inputs!$B$4-(C4-1))/(D4-(C4-1))) -> 0.19642857 | G4: =IF(C4=3,1,((MAX(Inputs!$B$4-(C4-1)-1,0)*2*B4)+(2*B4))/((Inputs!$B$4-(C4-1)+1)*(D4-(C4-1)))) -> 0.13095238 | H4: =IF(C4=3,1,((MAX(Inputs!$B$4-(C4-1)-1,0)*2)+(2))/((Inputs!$B$4-(C4-1)+1)*(D4-(C4-1)))) -> 0.032738095 | I4: =IF(C4=3,1,IF((C4-1)<B4,(B4-(C4-1))/(D4-(C4-1)),"")) | J4: =IF(C4=3,B4*COMBIN(Inputs!$B$4,3)/COMBIN(D4,3),J3*F4) -> 0.0021993909 | K4: =IF(C4=3,(Inputs!$B$4-3+1)*POWER(B4,3)/COMBIN(D4,3),K3*G4) -> 0.00041248651 | L4: =IF(C4=3,B4*(Inputs!$B$4-3+1)/COMBIN(D4,3),L3*H4) -> 1.6112754e-06 | M4: =IF(C4=3,IF(3<=B4,Inputs!$B$4*COMBIN(B4,3)/COMBIN(D4,3),""),IF(I4="","",M3*I4)) | N4: =-LN(J4) -> 6.1195748 | O4: =-LN(K4) -> 7.7933071 | P4: =-LN(L4) -> 13.338485 | Q4: =IF(M4="","",-LN(M4))
A5: 1 | B5: =Inputs!$B$5 -> 4 | C5: 6 | D5: =B5*Inputs!$B$4 -> 60 | E5: =IF(C5=3,"",C5-1) -> 5 | F5: =IF(C5=3,1,(Inputs!$B$4-(C5-1))/(D5-(C5-1))) -> 0.18181818 | G5: =IF(C5=3,1,((MAX(Inputs!$B$4-(C5-1)-1,0)*2*B5)+(2*B5))/((Inputs!$B$4-(C5-1)+1)*(D5-(C5-1)))) -> 0.1322314 | H5: =IF(C5=3,1,((MAX(Inputs!$B$4-(C5-1)-1,0)*2)+(2))/((Inputs!$B$4-(C5-1)+1)*(D5-(C5-1)))) -> 0.033057851 | I5: =IF(C5=3,1,IF((C5-1)<B5,(B5-(C5-1))/(D5-(C5-1)),"")) | J5: =IF(C5=3,B5*COMBIN(Inputs!$B$4,3)/COMBIN(D5,3),J4*F5) -> 0.00039988926 | K5: =IF(C5=3,(Inputs!$B$4-3+1)*POWER(B5,3)/COMBIN(D5,3),K4*G5) -> 5.454367e-05 | L5: =IF(C5=3,B5*(Inputs!$B$4-3+1)/COMBIN(D5,3),L4*H5) -> 5.3265303e-08 | M5: =IF(C5=3,IF(3<=B5,Inputs!$B$4*COMBIN(B5,3)/COMBIN(D5,3),""),IF(I5="","",M4*I5)) | N5: =-LN(J5) -> 7.8243229 | O5: =-LN(K5) -> 9.8165089 | P5: =-LN(L5) -> 16.747981 | Q5: =IF(M5="","",-LN(M5))
A6: 1 | B6: =Inputs!$B$5 -> 4 | C6: 7 | D6: =B6*Inputs!$B$4 -> 60 | E6: =IF(C6=3,"",C6-1) -> 6 | F6: =IF(C6=3,1,(Inputs!$B$4-(C6-1))/(D6-(C6-1))) -> 0.16666667 | G6: =IF(C6=3,1,((MAX(Inputs!$B$4-(C6-1)-1,0)*2*B6)+(2*B6))/((Inputs!$B$4-(C6-1)+1)*(D6-(C6-1)))) -> 0.13333333 | H6: =IF(C6=3,1,((MAX(Inputs!$B$4-(C6-1)-1,0)*2)+(2))/((Inputs!$B$4-(C6-1)+1)*(D6-(C6-1)))) -> 0.033333333 | I6: =IF(C6=3,1,IF((C6-1)<B6,(B6-(C6-1))/(D6-(C6-1)),"")) | J6: =IF(C6=3,B6*COMBIN(Inputs!$B$4,3)/COMBIN(D6,3),J5*F6) -> 6.664821e-05 | K6: =IF(C6=3,(Inputs!$B$4-3+1)*POWER(B6,3)/COMBIN(D6,3),K5*G6) -> 7.2724894e-06 | L6: =IF(C6=3,B6*(Inputs!$B$4-3+1)/COMBIN(D6,3),L5*H6) -> 1.7755101e-09 | M6: =IF(C6=3,IF(3<=B6,Inputs!$B$4*COMBIN(B6,3)/COMBIN(D6,3),""),IF(I6="","",M5*I6)) | N6: =-LN(J6) -> 9.6160824 | O6: =-LN(K6) -> 11.831412 | P6: =-LN(L6) -> 20.149178 | Q6: =IF(M6="","",-LN(M6))
A7: 1 | B7: =Inputs!$B$5 -> 4 | C7: 8 | D7: =B7*Inputs!$B$4 -> 60 | E7: =IF(C7=3,"",C7-1) -> 7 | F7: =IF(C7=3,1,(Inputs!$B$4-(C7-1))/(D7-(C7-1))) -> 0.1509434 | G7: =IF(C7=3,1,((MAX(Inputs!$B$4-(C7-1)-1,0)*2*B7)+(2*B7))/((Inputs!$B$4-(C7-1)+1)*(D7-(C7-1)))) -> 0.13417191 | H7: =IF(C7=3,1,((MAX(Inputs!$B$4-(C7-1)-1,0)*2)+(2))/((Inputs!$B$4-(C7-1)+1)*(D7-(C7-1)))) -> 0.033542977 | I7: =IF(C7=3,1,IF((C7-1)<B7,(B7-(C7-1))/(D7-(C7-1)),"")) | J7: =IF(C7=3,B7*COMBIN(Inputs!$B$4,3)/COMBIN(D7,3),J6*F7) -> 1.0060107e-05 | K7: =IF(C7=3,(Inputs!$B$4-3+1)*POWER(B7,3)/COMBIN(D7,3),K6*G7) -> 9.7576377e-07 | L7: =IF(C7=3,B7*(Inputs!$B$4-3+1)/COMBIN(D7,3),L6*H7) -> 5.9555894e-11 | M7: =IF(C7=3,IF(3<=B7,Inputs!$B$4*COMBIN(B7,3)/COMBIN(D7,3),""),IF(I7="","",M6*I7)) | N7: =-LN(J7) -> 11.506933 | O7: =-LN(K7) -> 13.840045 | P7: =-LN(L7) -> 23.544106 | Q7: =IF(M7="","",-LN(M7))
A8: 1 | B8: =Inputs!$B$5 -> 4 | C8: 9 | D8: =B8*Inputs!$B$4 -> 60 | E8: =IF(C8=3,"",C8-1) -> 8 | F8: =IF(C8=3,1,(Inputs!$B$4-(C8-1))/(D8-(C8-1))) -> 0.13461538 | G8: =IF(C8=3,1,((MAX(Inputs!$B$4-(C8-1)-1,0)*2*B8)+(2*B8))/((Inputs!$B$4-(C8-1)+1)*(D8-(C8-1)))) -> 0.13461538 | H8: =IF(C8=3,1,((MAX(Inputs!$B$4-(C8-1)-1,0)*2)+(2))/((Inputs!$B$4-(C8-1)+1)*(D8-(C8-1)))) -> 0.033653846 | I8: =IF(C8=3,1,IF((C8-1)<B8,(B8-(C8-1))/(D8-(C8-1)),"")) | J8: =IF(C8=3,B8*COMBIN(Inputs!$B$4,3)/COMBIN(D8,3),J7*F8) -> 1.3542452e-06 | K8: =IF(C8=3,(Inputs!$B$4-3+1)*POWER(B8,3)/COMBIN(D8,3),K7*G8) -> 1.3135282e-07 | L8: =IF(C8=3,B8*(Inputs!$B$4-3+1)/COMBIN(D8,3),L7*H8) -> 2.0042849e-12 | M8: =IF(C8=3,IF(3<=B8,Inputs!$B$4*COMBIN(B8,3)/COMBIN(D8,3),""),IF(I8="","",M7*I8)) | N8: =-LN(J8) -> 13.512266 | O8: =-LN(K8) -> 15.845379 | P8: =-LN(L8) -> 26.935734 | Q8: =IF(M8="","",-LN(M8))
A9: 1 | B9: =Inputs!$B$5 -> 4 | C9: 10 | D9: =B9*Inputs!$B$4 -> 60 | E9: =IF(C9=3,"",C9-1) -> 9 | F9: =IF(C9=3,1,(Inputs!$B$4-(C9-1))/(D9-(C9-1))) -> 0.11764706 | G9: =IF(C9=3,1,((MAX(Inputs!$B$4-(C9-1)-1,0)*2*B9)+(2*B9))/((Inputs!$B$4-(C9-1)+1)*(D9-(C9-1)))) -> 0.13445378 | H9: =IF(C9=3,1,((MAX(Inputs!$B$4-(C9-1)-1,0)*2)+(2))/((Inputs!$B$4-(C9-1)+1)*(D9-(C9-1)))) -> 0.033613445 | I9: =IF(C9=3,1,IF((C9-1)<B9,(B9-(C9-1))/(D9-(C9-1)),"")) | J9: =IF(C9=3,B9*COMBIN(Inputs!$B$4,3)/COMBIN(D9,3),J8*F9) -> 1.5932296e-07 | K9: =IF(C9=3,(Inputs!$B$4-3+1)*POWER(B9,3)/COMBIN(D9,3),K8*G9) -> 1.7660883e-08 | L9: =IF(C9=3,B9*(Inputs!$B$4-3+1)/COMBIN(D9,3),L8*H9) -> 6.7370921e-14 | M9: =IF(C9=3,IF(3<=B9,Inputs!$B$4*COMBIN(B9,3)/COMBIN(D9,3),""),IF(I9="","",M8*I9)) | N9: =-LN(J9) -> 15.652332 | O9: =-LN(K9) -> 17.851914 | P9: =-LN(L9) -> 30.328563 | Q9: =IF(M9="","",-LN(M9))
A10: 1 | B10: =Inputs!$B$5 -> 4 | C10: 11 | D10: =B10*Inputs!$B$4 -> 60 | E10: =IF(C10=3,"",C10-1) -> 10 | F10: =IF(C10=3,1,(Inputs!$B$4-(C10-1))/(D10-(C10-1))) -> 0.1 | G10: =IF(C10=3,1,((MAX(Inputs!$B$4-(C10-1)-1,0)*2*B10)+(2*B10))/((Inputs!$B$4-(C10-1)+1)*(D10-(C10-1)))) -> 0.13333333 | H10: =IF(C10=3,1,((MAX(Inputs!$B$4-(C10-1)-1,0)*2)+(2))/((Inputs!$B$4-(C10-1)+1)*(D10-(C10-1)))) -> 0.033333333 | I10: =IF(C10=3,1,IF((C10-1)<B10,(B10-(C10-1))/(D10-(C10-1)),"")) | J10: =IF(C10=3,B10*COMBIN(Inputs!$B$4,3)/COMBIN(D10,3),J9*F10) -> 1.5932296e-08 | K10: =IF(C10=3,(Inputs!$B$4-3+1)*POWER(B10,3)/COMBIN(D10,3),K9*G10) -> 2.3547844e-09 | L10: =IF(C10=3,B10*(Inputs!$B$4-3+1)/COMBIN(D10,3),L9*H10) -> 2.2456974e-15 | M10: =IF(C10=3,IF(3<=B10,Inputs!$B$4*COMBIN(B10,3)/COMBIN(D10,3),""),IF(I10="","",M9*I10)) | N10: =-LN(J10) -> 17.954918 | O10: =-LN(K10) -> 19.866817 | P10: =-LN(L10) -> 33.72976 | Q10: =IF(M10="","",-LN(M10))
A11: 1 | B11: =Inputs!$B$5 -> 4 | C11: 12 | D11: =B11*Inputs!$B$4 -> 60 | E11: =IF(C11=3,"",C11-1) -> 11 | F11: =IF(C11=3,1,(Inputs!$B$4-(C11-1))/(D11-(C11-1))) -> 0.081632653 | G11: =IF(C11=3,1,((MAX(Inputs!$B$4-(C11-1)-1,0)*2*B11)+(2*B11))/((Inputs!$B$4-(C11-1)+1)*(D11-(C11-1)))) -> 0.13061224 | H11: =IF(C11=3,1,((MAX(Inputs!$B$4-(C11-1)-1,0)*2)+(2))/((Inputs!$B$4-(C11-1)+1)*(D11-(C11-1)))) -> 0.032653061 | I11: =IF(C11=3,1,IF((C11-1)<B11,(B11-(C11-1))/(D11-(C11-1)),"")) | J11: =IF(C11=3,B11*COMBIN(Inputs!$B$4,3)/COMBIN(D11,3),J10*F11) -> 1.3005956e-09 | K11: =IF(C11=3,(Inputs!$B$4-3+1)*POWER(B11,3)/COMBIN(D11,3),K10*G11) -> 3.0756367e-10 | L11: =IF(C11=3,B11*(Inputs!$B$4-3+1)/COMBIN(D11,3),L10*H11) -> 7.3328894e-17 | M11: =IF(C11=3,IF(3<=B11,Inputs!$B$4*COMBIN(B11,3)/COMBIN(D11,3),""),IF(I11="","",M10*I11)) | N11: =-LN(J11) -> 20.460443 | O11: =-LN(K11) -> 21.902339 | P11: =-LN(L11) -> 37.151577 | Q11: =IF(M11="","",-LN(M11))
A12: 1 | B12: =Inputs!$B$5 -> 4 | C12: 13 | D12: =B12*Inputs!$B$4 -> 60 | E12: =IF(C12=3,"",C12-1) -> 12 | F12: =IF(C12=3,1,(Inputs!$B$4-(C12-1))/(D12-(C12-1))) -> 0.0625 | G12: =IF(C12=3,1,((MAX(Inputs!$B$4-(C12-1)-1,0)*2*B12)+(2*B12))/((Inputs!$B$4-(C12-1)+1)*(D12-(C12-1)))) -> 0.125 | H12: =IF(C12=3,1,((MAX(Inputs!$B$4-(C12-1)-1,0)*2)+(2))/((Inputs!$B$4-(C12-1)+1)*(D12-(C12-1)))) -> 0.03125 | I12: =IF(C12=3,1,IF((C12-1)<B12,(B12-(C12-1))/(D12-(C12-1)),"")) | J12: =IF(C12=3,B12*COMBIN(Inputs!$B$4,3)/COMBIN(D12,3),J11*F12) -> 8.1287227e-11 | K12: =IF(C12=3,(Inputs!$B$4-3+1)*POWER(B12,3)/COMBIN(D12,3),K11*G12) -> 3.8445459e-11 | L12: =IF(C12=3,B12*(Inputs!$B$4-3+1)/COMBIN(D12,3),L11*H12) -> 2.2915279e-18 | M12: =IF(C12=3,IF(3<=B12,Inputs!$B$4*COMBIN(B12,3)/COMBIN(D12,3),""),IF(I12="","",M11*I12)) | N12: =-LN(J12) -> 23.233032 | O12: =-LN(K12) -> 23.981781 | P12: =-LN(L12) -> 40.617313 | Q12: =IF(M12="","",-LN(M12))
A13: 1 | B13: =Inputs!$B$5 -> 4 | C13: 14 | D13: =B13*Inputs!$B$4 -> 60 | E13: =IF(C13=3,"",C13-1) -> 13 | F13: =IF(C13=3,1,(Inputs!$B$4-(C13-1))/(D13-(C13-1))) -> 0.042553191 | G13: =IF(C13=3,1,((MAX(Inputs!$B$4-(C13-1)-1,0)*2*B13)+(2*B13))/((Inputs!$B$4-(C13-1)+1)*(D13-(C13-1)))) -> 0.11347518 | H13: =IF(C13=3,1,((MAX(Inputs!$B$4-(C13-1)-1,0)*2)+(2))/((Inputs!$B$4-(C13-1)+1)*(D13-(C13-1)))) -> 0.028368794 | I13: =IF(C13=3,1,IF((C13-1)<B13,(B13-(C13-1))/(D13-(C13-1)),"")) | J13: =IF(C13=3,B13*COMBIN(Inputs!$B$4,3)/COMBIN(D13,3),J12*F13) -> 3.4590309e-12 | K13: =IF(C13=3,(Inputs!$B$4-3+1)*POWER(B13,3)/COMBIN(D13,3),K12*G13) -> 4.3626053e-12 | L13: =IF(C13=3,B13*(Inputs!$B$4-3+1)/COMBIN(D13,3),L12*H13) -> 6.5007884e-20 | M13: =IF(C13=3,IF(3<=B13,Inputs!$B$4*COMBIN(B13,3)/COMBIN(D13,3),""),IF(I13="","",M12*I13)) | N13: =-LN(J13) -> 26.390033 | O13: =-LN(K13) -> 26.157952 | P13: =-LN(L13) -> 44.179778 | Q13: =IF(M13="","",-LN(M13))
A14: 1 | B14: =Inputs!$B$5 -> 4 | C14: 15 | D14: =B14*Inputs!$B$4 -> 60 | E14: =IF(C14=3,"",C14-1) -> 14 | F14: =IF(C14=3,1,(Inputs!$B$4-(C14-1))/(D14-(C14-1))) -> 0.02173913 | G14: =IF(C14=3,1,((MAX(Inputs!$B$4-(C14-1)-1,0)*2*B14)+(2*B14))/((Inputs!$B$4-(C14-1)+1)*(D14-(C14-1)))) -> 0.086956522 | H14: =IF(C14=3,1,((MAX(Inputs!$B$4-(C14-1)-1,0)*2)+(2))/((Inputs!$B$4-(C14-1)+1)*(D14-(C14-1)))) -> 0.02173913 | I14: =IF(C14=3,1,IF((C14-1)<B14,(B14-(C14-1))/(D14-(C14-1)),"")) | J14: =IF(C14=3,B14*COMBIN(Inputs!$B$4,3)/COMBIN(D14,3),J13*F14) -> 7.5196325e-14 | K14: =IF(C14=3,(Inputs!$B$4-3+1)*POWER(B14,3)/COMBIN(D14,3),K13*G14) -> 3.7935698e-13 | L14: =IF(C14=3,B14*(Inputs!$B$4-3+1)/COMBIN(D14,3),L13*H14) -> 1.4132149e-21 | M14: =IF(C14=3,IF(3<=B14,Inputs!$B$4*COMBIN(B14,3)/COMBIN(D14,3),""),IF(I14="","",M13*I14)) | N14: =-LN(J14) -> 30.218674 | O14: =-LN(K14) -> 28.600299 | P14: =-LN(L14) -> 48.00842 | Q14: =IF(M14="","",-LN(M14))
A15: 2 | B15: =Inputs!$B$6 -> 5 | C15: 3 | D15: =B15*Inputs!$B$4 -> 75 | E15: =IF(C15=3,"",C15-1) | F15: =IF(C15=3,1,(Inputs!$B$4-(C15-1))/(D15-(C15-1))) -> 1 | G15: =IF(C15=3,1,((MAX(Inputs!$B$4-(C15-1)-1,0)*2*B15)+(2*B15))/((Inputs!$B$4-(C15-1)+1)*(D15-(C15-1)))) -> 1 | H15: =IF(C15=3,1,((MAX(Inputs!$B$4-(C15-1)-1,0)*2)+(2))/((Inputs!$B$4-(C15-1)+1)*(D15-(C15-1)))) -> 1 | I15: =IF(C15=3,1,IF((C15-1)<B15,(B15-(C15-1))/(D15-(C15-1)),"")) -> 1 | J15: =IF(C15=3,B15*COMBIN(Inputs!$B$4,3)/COMBIN(D15,3),J14*F15) -> 0.033691225 | K15: =IF(C15=3,(Inputs!$B$4-3+1)*POWER(B15,3)/COMBIN(D15,3),K14*G15) -> 0.024065161 | L15: =IF(C15=3,B15*(Inputs!$B$4-3+1)/COMBIN(D15,3),L14*H15) -> 0.00096260644 | M15: =IF(C15=3,IF(3<=B15,Inputs!$B$4*COMBIN(B15,3)/COMBIN(D15,3),""),IF(I15="","",M14*I15)) -> 0.0022213995 | N15: =-LN(J15) -> 3.3905178 | O15: =-LN(K15) -> 3.7269901 | P15: =-LN(L15) -> 6.9458659 | Q15: =IF(M15="","",-LN(M15)) -> 6.1096179
A16: 2 | B16: =Inputs!$B$6 -> 5 | C16: 4 | D16: =B16*Inputs!$B$4 -> 75 | E16: =IF(C16=3,"",C16-1) -> 3 | F16: =IF(C16=3,1,(Inputs!$B$4-(C16-1))/(D16-(C16-1))) -> 0.16666667 | G16: =IF(C16=3,1,((MAX(Inputs!$B$4-(C16-1)-1,0)*2*B16)+(2*B16))/((Inputs!$B$4-(C16-1)+1)*(D16-(C16-1)))) -> 0.12820513 | H16: =IF(C16=3,1,((MAX(Inputs!$B$4-(C16-1)-1,0)*2)+(2))/((Inputs!$B$4-(C16-1)+1)*(D16-(C16-1)))) -> 0.025641026 | I16: =IF(C16=3,1,IF((C16-1)<B16,(B16-(C16-1))/(D16-(C16-1)),"")) -> 0.027777778 | J16: =IF(C16=3,B16*COMBIN(Inputs!$B$4,3)/COMBIN(D16,3),J15*F16) -> 0.0056152042 | K16: =IF(C16=3,(Inputs!$B$4-3+1)*POWER(B16,3)/COMBIN(D16,3),K15*G16) -> 0.0030852771 | L16: =IF(C16=3,B16*(Inputs!$B$4-3+1)/COMBIN(D16,3),L15*H16) -> 2.4682216e-05 | M16: =IF(C16=3,IF(3<=B16,Inputs!$B$4*COMBIN(B16,3)/COMBIN(D16,3),""),IF(I16="","",M15*I16)) -> 6.1705541e-05 | N16: =-LN(J16) -> 5.1822773 | O16: =-LN(K16) -> 5.7811138 | P16: =-LN(L16) -> 10.609428 | Q16: =IF(M16="","",-LN(M16)) -> 9.6931368
A17: 2 | B17: =Inputs!$B$6 -> 5 | C17: 5 | D17: =B17*Inputs!$B$4 -> 75 | E17: =IF(C17=3,"",C17-1) -> 4 | F17: =IF(C17=3,1,(Inputs!$B$4-(C17-1))/(D17-(C17-1))) -> 0.15492958 | G17: =IF(C17=3,1,((MAX(Inputs!$B$4-(C17-1)-1,0)*2*B17)+(2*B17))/((Inputs!$B$4-(C17-1)+1)*(D17-(C17-1)))) -> 0.12910798 | H17: =IF(C17=3,1,((MAX(Inputs!$B$4-(C17-1)-1,0)*2)+(2))/((Inputs!$B$4-(C17-1)+1)*(D17-(C17-1)))) -> 0.025821596 | I17: =IF(C17=3,1,IF((C17-1)<B17,(B17-(C17-1))/(D17-(C17-1)),"")) -> 0.014084507 | J17: =IF(C17=3,B17*COMBIN(Inputs!$B$4,3)/COMBIN(D17,3),J16*F17) -> 0.00086996122 | K17: =IF(C17=3,(Inputs!$B$4-3+1)*POWER(B17,3)/COMBIN(D17,3),K16*G17) -> 0.00039833389 | L17: =IF(C17=3,B17*(Inputs!$B$4-3+1)/COMBIN(D17,3),L16*H17) -> 6.3733423e-07 | M17: =IF(C17=3,IF(3<=B17,Inputs!$B$4*COMBIN(B17,3)/COMBIN(D17,3),""),IF(I17="","",M16*I17)) -> 8.6909213e-07 | N17: =-LN(J17) -> 7.0470619 | O17: =-LN(K17) -> 7.82822 | P17: =-LN(L17) -> 14.265972 | Q17: =IF(M17="","",-LN(M17)) -> 13.955817
A18: 2 | B18: =Inputs!$B$6 -> 5 | C18: 6 | D18: =B18*Inputs!$B$4 -> 75 | E18: =IF(C18=3,"",C18-1) -> 5 | F18: =IF(C18=3,1,(Inputs!$B$4-(C18-1))/(D18-(C18-1))) -> 0.14285714 | G18: =IF(C18=3,1,((MAX(Inputs!$B$4-(C18-1)-1,0)*2*B18)+(2*B18))/((Inputs!$B$4-(C18-1)+1)*(D18-(C18-1)))) -> 0.12987013 | H18: =IF(C18=3,1,((MAX(Inputs!$B$4-(C18-1)-1,0)*2)+(2))/((Inputs!$B$4-(C18-1)+1)*(D18-(C18-1)))) -> 0.025974026 | I18: =IF(C18=3,1,IF((C18-1)<B18,(B18-(C18-1))/(D18-(C18-1)),"")) | J18: =IF(C18=3,B18*COMBIN(Inputs!$B$4,3)/COMBIN(D18,3),J17*F18) -> 0.00012428017 | K18: =IF(C18=3,(Inputs!$B$4-3+1)*POWER(B18,3)/COMBIN(D18,3),K17*G18) -> 5.1731674e-05 | L18: =IF(C18=3,B18*(Inputs!$B$4-3+1)/COMBIN(D18,3),L17*H18) -> 1.6554136e-08 | M18: =IF(C18=3,IF(3<=B18,Inputs!$B$4*COMBIN(B18,3)/COMBIN(D18,3),""),IF(I18="","",M17*I18)) | N18: =-LN(J18) -> 8.9929721 | O18: =-LN(K18) -> 9.8694403 | P18: =-LN(L18) -> 17.91663 | Q18: =IF(M18="","",-LN(M18))
A19: 2 | B19: =Inputs!$B$6 -> 5 | C19: 7 | D19: =B19*Inputs!$B$4 -> 75 | E19: =IF(C19=3,"",C19-1) -> 6 | F19: =IF(C19=3,1,(Inputs!$B$4-(C19-1))/(D19-(C19-1))) -> 0.13043478 | G19: =IF(C19=3,1,((MAX(Inputs!$B$4-(C19-1)-1,0)*2*B19)+(2*B19))/((Inputs!$B$4-(C19-1)+1)*(D19-(C19-1)))) -> 0.13043478 | H19: =IF(C19=3,1,((MAX(Inputs!$B$4-(C19-1)-1,0)*2)+(2))/((Inputs!$B$4-(C19-1)+1)*(D19-(C19-1)))) -> 0.026086957 | I19: =IF(C19=3,1,IF((C19-1)<B19,(B19-(C19-1))/(D19-(C19-1)),"")) | J19: =IF(C19=3,B19*COMBIN(Inputs!$B$4,3)/COMBIN(D19,3),J18*F19) -> 1.6210458e-05 | K19: =IF(C19=3,(Inputs!$B$4-3+1)*POWER(B19,3)/COMBIN(D19,3),K18*G19) -> 6.7476097e-06 | L19: =IF(C19=3,B19*(Inputs!$B$4-3+1)/COMBIN(D19,3),L18*H19) -> 4.3184702e-10 | M19: =IF(C19=3,IF(3<=B19,Inputs!$B$4*COMBIN(B19,3)/COMBIN(D19,3),""),IF(I19="","",M18*I19)) | N19: =-LN(J19) -> 11.029854 | O19: =-LN(K19) -> 11.906322 | P19: =-LN(L19) -> 21.56295 | Q19: =IF(M19="","",-LN(M19))
A20: 2 | B20: =Inputs!$B$6 -> 5 | C20: 8 | D20: =B20*Inputs!$B$4 -> 75 | E20: =IF(C20=3,"",C20-1) -> 7 | F20: =IF(C20=3,1,(Inputs!$B$4-(C20-1))/(D20-(C20-1))) -> 0.11764706 | G20: =IF(C20=3,1,((MAX(Inputs!$B$4-(C20-1)-1,0)*2*B20)+(2*B20))/((Inputs!$B$4-(C20-1)+1)*(D20-(C20-1)))) -> 0.13071895 | H20: =IF(C20=3,1,((MAX(Inputs!$B$4-(C20-1)-1,0)*2)+(2))/((Inputs!$B$4-(C20-1)+1)*(D20-(C20-1)))) -> 0.026143791 | I20: =IF(C20=3,1,IF((C20-1)<B20,(B20-(C20-1))/(D20-(C20-1)),"")) | J20: =IF(C20=3,B20*COMBIN(Inputs!$B$4,3)/COMBIN(D20,3),J19*F20) -> 1.9071127e-06 | K20: =IF(C20=3,(Inputs!$B$4-3+1)*POWER(B20,3)/COMBIN(D20,3),K19*G20) -> 8.8204048e-07 | L20: =IF(C20=3,B20*(Inputs!$B$4-3+1)/COMBIN(D20,3),L19*H20) -> 1.1290118e-11 | M20: =IF(C20=3,IF(3<=B20,Inputs!$B$4*COMBIN(B20,3)/COMBIN(D20,3),""),IF(I20="","",M19*I20)) | N20: =-LN(J20) -> 13.16992 | O20: =-LN(K20) -> 13.941028 | P20: =-LN(L20) -> 25.207093 | Q20: =IF(M20="","",-LN(M20))
A21: 2 | B21: =Inputs!$B$6 -> 5 | C21: 9 | D21: =B21*Inputs!$B$4 -> 75 | E21: =IF(C21=3,"",C21-1) -> 8 | F21: =IF(C21=3,1,(Inputs!$B$4-(C21-1))/(D21-(C21-1))) -> 0.10447761 | G21: =IF(C21=3,1,((MAX(Inputs!$B$4-(C21-1)-1,0)*2*B21)+(2*B21))/((Inputs!$B$4-(C21-1)+1)*(D21-(C21-1)))) -> 0.13059701 | H21: =IF(C21=3,1,((MAX(Inputs!$B$4-(C21-1)-1,0)*2)+(2))/((Inputs!$B$4-(C21-1)+1)*(D21-(C21-1)))) -> 0.026119403 | I21: =IF(C21=3,1,IF((C21-1)<B21,(B21-(C21-1))/(D21-(C21-1)),"")) | J21: =IF(C21=3,B21*COMBIN(Inputs!$B$4,3)/COMBIN(D21,3),J20*F21) -> 1.9925058e-07 | K21: =IF(C21=3,(Inputs!$B$4-3+1)*POWER(B21,3)/COMBIN(D21,3),K20*G21) -> 1.1519185e-07 | L21: =IF(C21=3,B21*(Inputs!$B$4-3+1)/COMBIN(D21,3),L20*H21) -> 2.9489115e-13 | M21: =IF(C21=3,IF(3<=B21,Inputs!$B$4*COMBIN(B21,3)/COMBIN(D21,3),""),IF(I21="","",M20*I21)) | N21: =-LN(J21) -> 15.428703 | O21: =-LN(K21) -> 15.976667 | P21: =-LN(L21) -> 28.85217 | Q21: =IF(M21="","",-LN(M21))
A22: 2 | B22: =Inputs!$B$6 -> 5 | C22: 10 | D22: =B22*Inputs!$B$4 -> 75 | E22: =IF(C22=3,"",C22-1) -> 9 | F22: =IF(C22=3,1,(Inputs!$B$4-(C22-1))/(D22-(C22-1))) -> 0.090909091 | G22: =IF(C22=3,1,((MAX(Inputs!$B$4-(C22-1)-1,0)*2*B22)+(2*B22))/((Inputs!$B$4-(C22-1)+1)*(D22-(C22-1)))) -> 0.12987013 | H22: =IF(C22=3,1,((MAX(Inputs!$B$4-(C22-1)-1,0)*2)+(2))/((Inputs!$B$4-(C22-1)+1)*(D22-(C22-1)))) -> 0.025974026 | I22: =IF(C22=3,1,IF((C22-1)<B22,(B22-(C22-1))/(D22-(C22-1)),"")) | J22: =IF(C22=3,B22*COMBIN(Inputs!$B$4,3)/COMBIN(D22,3),J21*F22) -> 1.8113689e-08 | K22: =IF(C22=3,(Inputs!$B$4-3+1)*POWER(B22,3)/COMBIN(D22,3),K21*G22) -> 1.4959981e-08 | L22: =IF(C22=3,B22*(Inputs!$B$4-3+1)/COMBIN(D22,3),L21*H22) -> 7.6595103e-15 | M22: =IF(C22=3,IF(3<=B22,Inputs!$B$4*COMBIN(B22,3)/COMBIN(D22,3),""),IF(I22="","",M21*I22)) | N22: =-LN(J22) -> 17.826598 | O22: =-LN(K22) -> 18.017887 | P22: =-LN(L22) -> 32.502828 | Q22: =IF(M22="","",-LN(M22))
A23: 2 | B23: =Inputs!$B$6 -> 5 | C23: 11 | D23: =B23*Inputs!$B$4 -> 75 | E23: =IF(C23=3,"",C23-1) -> 10 | F23: =IF(C23=3,1,(Inputs!$B$4-(C23-1))/(D23-(C23-1))) -> 0.076923077 | G23: =IF(C23=3,1,((MAX(Inputs!$B$4-(C23-1)-1,0)*2*B23)+(2*B23))/((Inputs!$B$4-(C23-1)+1)*(D23-(C23-1)))) -> 0.12820513 | H23: =IF(C23=3,1,((MAX(Inputs!$B$4-(C23-1)-1,0)*2)+(2))/((Inputs!$B$4-(C23-1)+1)*(D23-(C23-1)))) -> 0.025641026 | I23: =IF(C23=3,1,IF((C23-1)<B23,(B23-(C23-1))/(D23-(C23-1)),"")) | J23: =IF(C23=3,B23*COMBIN(Inputs!$B$4,3)/COMBIN(D23,3),J22*F23) -> 1.3933607e-09 | K23: =IF(C23=3,(Inputs!$B$4-3+1)*POWER(B23,3)/COMBIN(D23,3),K22*G23) -> 1.9179463e-09 | L23: =IF(C23=3,B23*(Inputs!$B$4-3+1)/COMBIN(D23,3),L22*H23) -> 1.963977e-16 | M23: =IF(C23=3,IF(3<=B23,Inputs!$B$4*COMBIN(B23,3)/COMBIN(D23,3),""),IF(I23="","",M22*I23)) | N23: =-LN(J23) -> 20.391547 | O23: =-LN(K23) -> 20.072011 | P23: =-LN(L23) -> 36.16639 | Q23: =IF(M23="","",-LN(M23))
A24: 2 | B24: =Inputs!$B$6 -> 5 | C24: 12 | D24: =B24*Inputs!$B$4 -> 75 | E24: =IF(C24=3,"",C24-1) -> 11 | F24: =IF(C24=3,1,(Inputs!$B$4-(C24-1))/(D24-(C24-1))) -> 0.0625 | G24: =IF(C24=3,1,((MAX(Inputs!$B$4-(C24-1)-1,0)*2*B24)+(2*B24))/((Inputs!$B$4-(C24-1)+1)*(D24-(C24-1)))) -> 0.125 | H24: =IF(C24=3,1,((MAX(Inputs!$B$4-(C24-1)-1,0)*2)+(2))/((Inputs!$B$4-(C24-1)+1)*(D24-(C24-1)))) -> 0.025 | I24: =IF(C24=3,1,IF((C24-1)<B24,(B24-(C24-1))/(D24-(C24-1)),"")) | J24: =IF(C24=3,B24*COMBIN(Inputs!$B$4,3)/COMBIN(D24,3),J23*F24) -> 8.7085042e-11 | K24: =IF(C24=3,(Inputs!$B$4-3+1)*POWER(B24,3)/COMBIN(D24,3),K23*G24) -> 2.3974329e-10 | L24: =IF(C24=3,B24*(Inputs!$B$4-3+1)/COMBIN(D24,3),L23*H24) -> 4.9099425e-18 | M24: =IF(C24=3,IF(3<=B24,Inputs!$B$4*COMBIN(B24,3)/COMBIN(D24,3),""),IF(I24="","",M23*I24)) | N24: =-LN(J24) -> 23.164136 | O24: =-LN(K24) -> 22.151452 | P24: =-LN(L24) -> 39.855269 | Q24: =IF(M24="","",-LN(M24))
A25: 2 | B25: =Inputs!$B$6 -> 5 | C25: 13 | D25: =B25*Inputs!$B$4 -> 75 | E25: =IF(C25=3,"",C25-1) -> 12 | F25: =IF(C25=3,1,(Inputs!$B$4-(C25-1))/(D25-(C25-1))) -> 0.047619048 | G25: =IF(C25=3,1,((MAX(Inputs!$B$4-(C25-1)-1,0)*2*B25)+(2*B25))/((Inputs!$B$4-(C25-1)+1)*(D25-(C25-1)))) -> 0.11904762 | H25: =IF(C25=3,1,((MAX(Inputs!$B$4-(C25-1)-1,0)*2)+(2))/((Inputs!$B$4-(C25-1)+1)*(D25-(C25-1)))) -> 0.023809524 | I25: =IF(C25=3,1,IF((C25-1)<B25,(B25-(C25-1))/(D25-(C25-1)),"")) | J25: =IF(C25=3,B25*COMBIN(Inputs!$B$4,3)/COMBIN(D25,3),J24*F25) -> 4.1469067e-12 | K25: =IF(C25=3,(Inputs!$B$4-3+1)*POWER(B25,3)/COMBIN(D25,3),K24*G25) -> 2.8540867e-11 | L25: =IF(C25=3,B25*(Inputs!$B$4-3+1)/COMBIN(D25,3),L24*H25) -> 1.1690339e-19 | M25: =IF(C25=3,IF(3<=B25,Inputs!$B$4*COMBIN(B25,3)/COMBIN(D25,3),""),IF(I25="","",M24*I25)) | N25: =-LN(J25) -> 26.208658 | O25: =-LN(K25) -> 24.279684 | P25: =-LN(L25) -> 43.592939 | Q25: =IF(M25="","",-LN(M25))
A26: 2 | B26: =Inputs!$B$6 -> 5 | C26: 14 | D26: =B26*Inputs!$B$4 -> 75 | E26: =IF(C26=3,"",C26-1) -> 13 | F26: =IF(C26=3,1,(Inputs!$B$4-(C26-1))/(D26-(C26-1))) -> 0.032258065 | G26: =IF(C26=3,1,((MAX(Inputs!$B$4-(C26-1)-1,0)*2*B26)+(2*B26))/((Inputs!$B$4-(C26-1)+1)*(D26-(C26-1)))) -> 0.10752688 | H26: =IF(C26=3,1,((MAX(Inputs!$B$4-(C26-1)-1,0)*2)+(2))/((Inputs!$B$4-(C26-1)+1)*(D26-(C26-1)))) -> 0.021505376 | I26: =IF(C26=3,1,IF((C26-1)<B26,(B26-(C26-1))/(D26-(C26-1)),"")) | J26: =IF(C26=3,B26*COMBIN(Inputs!$B$4,3)/COMBIN(D26,3),J25*F26) -> 1.3377119e-13 | K26: =IF(C26=3,(Inputs!$B$4-3+1)*POWER(B26,3)/COMBIN(D26,3),K25*G26) -> 3.0689105e-12 | L26: =IF(C26=3,B26*(Inputs!$B$4-3+1)/COMBIN(D26,3),L25*H26) -> 2.5140515e-21 | M26: =IF(C26=3,IF(3<=B26,Inputs!$B$4*COMBIN(B26,3)/COMBIN(D26,3),""),IF(I26="","",M25*I26)) | N26: =-LN(J26) -> 29.642646 | O26: =-LN(K26) -> 26.509699 | P26: =-LN(L26) -> 47.432391 | Q26: =IF(M26="","",-LN(M26))
A27: 2 | B27: =Inputs!$B$6 -> 5 | C27: 15 | D27: =B27*Inputs!$B$4 -> 75 | E27: =IF(C27=3,"",C27-1) -> 14 | F27: =IF(C27=3,1,(Inputs!$B$4-(C27-1))/(D27-(C27-1))) -> 0.016393443 | G27: =IF(C27=3,1,((MAX(Inputs!$B$4-(C27-1)-1,0)*2*B27)+(2*B27))/((Inputs!$B$4-(C27-1)+1)*(D27-(C27-1)))) -> 0.081967213 | H27: =IF(C27=3,1,((MAX(Inputs!$B$4-(C27-1)-1,0)*2)+(2))/((Inputs!$B$4-(C27-1)+1)*(D27-(C27-1)))) -> 0.016393443 | I27: =IF(C27=3,1,IF((C27-1)<B27,(B27-(C27-1))/(D27-(C27-1)),"")) | J27: =IF(C27=3,B27*COMBIN(Inputs!$B$4,3)/COMBIN(D27,3),J26*F27) -> 2.1929703e-15 | K27: =IF(C27=3,(Inputs!$B$4-3+1)*POWER(B27,3)/COMBIN(D27,3),K26*G27) -> 2.5155004e-13 | L27: =IF(C27=3,B27*(Inputs!$B$4-3+1)/COMBIN(D27,3),L26*H27) -> 4.1213958e-23 | M27: =IF(C27=3,IF(3<=B27,Inputs!$B$4*COMBIN(B27,3)/COMBIN(D27,3),""),IF(I27="","",M26*I27)) | N27: =-LN(J27) -> 33.753519 | O27: =-LN(K27) -> 29.011134 | P27: =-LN(L27) -> 51.543265 | Q27: =IF(M27="","",-LN(M27))

Sheet Combined_Model
A1: Deck | B1: Energies E | C1: Size n | D1: C raw prob | E1: C marginal prob | F1: C combined prob | G1: C combined diff | H1: T raw prob | I1: T marginal prob | J1: T combined prob | K1: T combined diff | L1: PT raw prob | M1: PT marginal prob | N1: PT combined prob | O1: PT combined diff | P1: Ench raw prob | Q1: Ench marginal prob | R1: Ench combined prob | S1: Ench combined diff
A2: 1 | B2: =Inputs!$B$5 -> 4 | C2: 3 | D2: =Raw_Model!G2 -> 0.053185272 | E2: =Marginal_Model!J2 -> 0.053185272 | F2: =EXP(-(Inputs!$B$7*Raw_Model!N2+(1-Inputs!$B$7)*Marginal_Model!N2)) -> 0.053185272 | G2: =-LN(F2) -> 2.9339738 | H2: =Raw_Model!I2 -> 0.024313267 | I2: =Marginal_Model!K2 -> 0.024313267 | J2: =EXP(-(Inputs!$B$7*Raw_Model!O2+(1-Inputs!$B$7)*Marginal_Model!O2)) -> 0.024313267 | K2: =-LN(J2) -> 3.7167331 | L2: =Raw_Model!K2 -> 0.0015195792 | M2: =Marginal_Model!L2 -> 0.0015195792 | N2: =EXP(-(Inputs!$B$7*Raw_Model!P2+(1-Inputs!$B$7)*Marginal_Model!P2)) -> 0.0015195792 | O2: =-LN(N2) -> 6.4893218 | P2: =Raw_Model!M2 -> 0.0017533606 | Q2: =Marginal_Model!M2 -> 0.0017533606 | R2: =IF(P2="","",EXP(-(Inputs!$B$7*Raw_Model!Q2+(1-Inputs!$B$7)*Marginal_Model!Q2))) -> 0.0017533606 | S2: =IF(R2="","",-LN(R2)) -> 6.346221
A3: 1 | B3: =Inputs!$B$5 -> 4 | C3: 4 | D3: =Raw_Model!G3 -> 0.011196899 | E3: =Marginal_Model!J3 -> 0.011196899 | F3: =EXP(-(Inputs!$B$7*Raw_Model!N3+(1-Inputs!$B$7)*Marginal_Model!N3)) -> 0.011196899 | G3: =-LN(F3) -> 4.4921184 | H3: =Raw_Model!I3 -> 0.0062997939 | I3: =Marginal_Model!K3 -> 0.003149897 | J3: =EXP(-(Inputs!$B$7*Raw_Model!O3+(1-Inputs!$B$7)*Marginal_Model!O3)) -> 0.0054842891 | K3: =-LN(J3) -> 5.2058678 | L3: =Raw_Model!K3 -> 9.843428e-05 | M3: =Marginal_Model!L3 -> 4.921714e-05 | N3: =EXP(-(Inputs!$B$7*Raw_Model!P3+(1-Inputs!$B$7)*Marginal_Model!P3)) -> 8.5692018e-05 | O3: =-LN(N3) -> 9.3647509 | P3: =Raw_Model!M3 -> 3.0760712e-05 | Q3: =Marginal_Model!M3 -> 3.0760712e-05 | R3: =IF(P3="","",EXP(-(Inputs!$B$7*Raw_Model!Q3+(1-Inputs!$B$7)*Marginal_Model!Q3))) -> 3.0760712e-05 | S3: =IF(R3="","",-LN(R3)) -> 10.389272
A4: 1 | B4: =Inputs!$B$5 -> 4 | C4: 5 | D4: =Raw_Model!G4 -> 0.0021993909 | E4: =Marginal_Model!J4 -> 0.0021993909 | F4: =EXP(-(Inputs!$B$7*Raw_Model!N4+(1-Inputs!$B$7)*Marginal_Model!N4)) -> 0.0021993909 | G4: =-LN(F4) -> 6.1195748 | H4: =Raw_Model!I4 -> 0.0020624325 | I4: =Marginal_Model!K4 -> 0.00041248651 | J4: =EXP(-(Inputs!$B$7*Raw_Model!O4+(1-Inputs!$B$7)*Marginal_Model!O4)) -> 0.0014948092 | K4: =-LN(J4) -> 6.5057567 | L4: =Raw_Model!K4 -> 8.0563771e-06 | M4: =Marginal_Model!L4 -> 1.6112754e-06 | N4: =EXP(-(Inputs!$B$7*Raw_Model!P4+(1-Inputs!$B$7)*Marginal_Model!P4)) -> 5.8390983e-06 | O4: =-LN(N4) -> 12.050934 | P4: =Raw_Model!M4 | Q4: =Marginal_Model!M4 | R4: =IF(P4="","",EXP(-(Inputs!$B$7*Raw_Model!Q4+(1-Inputs!$B$7)*Marginal_Model!Q4))) | S4: =IF(R4="","",-LN(R4))
A5: 1 | B5: =Inputs!$B$5 -> 4 | C5: 6 | D5: =Raw_Model!G5 -> 0.00039988926 | E5: =Marginal_Model!J5 -> 0.00039988926 | F5: =EXP(-(Inputs!$B$7*Raw_Model!N5+(1-Inputs!$B$7)*Marginal_Model!N5)) -> 0.00039988926 | G5: =-LN(F5) -> 7.8243229 | H5: =Raw_Model!I5 -> 0.00081815505 | I5: =Marginal_Model!K5 -> 5.454367e-05 | J5: =EXP(-(Inputs!$B$7*Raw_Model!O5+(1-Inputs!$B$7)*Marginal_Model!O5)) -> 0.00047601141 | K5: =-LN(J5) -> 7.6500687 | L5: =Raw_Model!K5 -> 7.9897954e-07 | M5: =Marginal_Model!L5 -> 5.3265303e-08 | N5: =EXP(-(Inputs!$B$7*Raw_Model!P5+(1-Inputs!$B$7)*Marginal_Model!P5)) -> 4.6485489e-07 | O5: =-LN(N5) -> 14.581541 | P5: =Raw_Model!M5 | Q5: =Marginal_Model!M5 | R5: =IF(P5="","",EXP(-(Inputs!$B$7*Raw_Model!Q5+(1-Inputs!$B$7)*Marginal_Model!Q5))) | S5: =IF(R5="","",-LN(R5))
A6: 1 | B6: =Inputs!$B$5 -> 4 | C6: 7 | D6: =Raw_Model!G6 -> 6.664821e-05 | E6: =Marginal_Model!J6 -> 6.664821e-05 | F6: =EXP(-(Inputs!$B$7*Raw_Model!N6+(1-Inputs!$B$7)*Marginal_Model!N6)) -> 6.664821e-05 | G6: =-LN(F6) -> 9.6160824 | H6: =Raw_Model!I6 -> 0.00038180569 | I6: =Marginal_Model!K6 -> 7.2724894e-06 | J6: =EXP(-(Inputs!$B$7*Raw_Model!O6+(1-Inputs!$B$7)*Marginal_Model!O6)) -> 0.00017290619 | K6: =-LN(J6) -> 8.6627614 | L6: =Raw_Model!K6 -> 9.321428e-08 | M6: =Marginal_Model!L6 -> 1.7755101e-09 | N6: =EXP(-(Inputs!$B$7*Raw_Model!P6+(1-Inputs!$B$7)*Marginal_Model!P6)) -> 4.2213425e-08 | O6: =-LN(N6) -> 16.980528 | P6: =Raw_Model!M6 | Q6: =Marginal_Model!M6 | R6: =IF(P6="","",EXP(-(Inputs!$B$7*Raw_Model!Q6+(1-Inputs!$B$7)*Marginal_Model!Q6))) | S6: =IF(R6="","",-LN(R6))
A7: 1 | B7: =Inputs!$B$5 -> 4 | C7: 8 | D7: =Raw_Model!G7 -> 1.0060107e-05 | E7: =Marginal_Model!J7 -> 1.0060107e-05 | F7: =EXP(-(Inputs!$B$7*Raw_Model!N7+(1-Inputs!$B$7)*Marginal_Model!N7)) -> 1.0060107e-05 | G7: =-LN(F7) -> 11.506933 | H7: =Raw_Model!I7 -> 0.00020491039 | I7: =Marginal_Model!K7 -> 9.7576377e-07 | J7: =EXP(-(Inputs!$B$7*Raw_Model!O7+(1-Inputs!$B$7)*Marginal_Model!O7)) -> 7.0326682e-05 | K7: =-LN(J7) -> 9.5623593 | L7: =Raw_Model!K7 -> 1.2506738e-08 | M7: =Marginal_Model!L7 -> 5.9555894e-11 | N7: =EXP(-(Inputs!$B$7*Raw_Model!P7+(1-Inputs!$B$7)*Marginal_Model!P7)) -> 4.2924e-09 | O7: =-LN(N7) -> 19.26642 | P7: =Raw_Model!M7 | Q7: =Marginal_Model!M7 | R7: =IF(P7="","",EXP(-(Inputs!$B$7*Raw_Model!Q7+(1-Inputs!$B$7)*Marginal_Model!Q7))) | S7: =IF(R7="","",-LN(R7))
A8: 1 | B8: =Inputs!$B$5 -> 4 | C8: 9 | D8: =Raw_Model!G8 -> 1.3542452e-06 | E8: =Marginal_Model!J8 -> 1.3542452e-06 | F8: =EXP(-(Inputs!$B$7*Raw_Model!N8+(1-Inputs!$B$7)*Marginal_Model!N8)) -> 1.3542452e-06 | G8: =-LN(F8) -> 13.512266 | H8: =Raw_Model!I8 -> 0.00012412841 | I8: =Marginal_Model!K8 -> 1.3135282e-07 | J8: =EXP(-(Inputs!$B$7*Raw_Model!O8+(1-Inputs!$B$7)*Marginal_Model!O8)) -> 3.1534419e-05 | K8: =-LN(J8) -> 10.364431 | L8: =Raw_Model!K8 -> 1.8940492e-09 | M8: =Marginal_Model!L8 -> 2.0042849e-12 | N8: =EXP(-(Inputs!$B$7*Raw_Model!P8+(1-Inputs!$B$7)*Marginal_Model!P8)) -> 4.8117705e-10 | O8: =-LN(N8) -> 21.454786 | P8: =Raw_Model!M8 | Q8: =Marginal_Model!M8 | R8: =IF(P8="","",EXP(-(Inputs!$B$7*Raw_Model!Q8+(1-Inputs!$B$7)*Marginal_Model!Q8))) | S8: =IF(R8="","",-LN(R8))
A9: 1 | B9: =Inputs!$B$5 -> 4 | C9: 10 | D9: =Raw_Model!G9 -> 1.5932296e-07 | E9: =Marginal_Model!J9 -> 1.5932296e-07 | F9: =EXP(-(Inputs!$B$7*Raw_Model!N9+(1-Inputs!$B$7)*Marginal_Model!N9)) -> 1.5932296e-07 | G9: =-LN(F9) -> 15.652332 | H9: =Raw_Model!I9 -> 8.3447671e-05 | I9: =Marginal_Model!K9 -> 1.7660883e-08 | J9: =EXP(-(Inputs!$B$7*Raw_Model!O9+(1-Inputs!$B$7)*Marginal_Model!O9)) -> 1.5365046e-05 | K9: =-LN(J9) -> 11.083415 | L9: =Raw_Model!K9 -> 3.183276e-10 | M9: =Marginal_Model!L9 -> 6.7370921e-14 | N9: =EXP(-(Inputs!$B$7*Raw_Model!P9+(1-Inputs!$B$7)*Marginal_Model!P9)) -> 5.8612998e-11 | O9: =-LN(N9) -> 23.560065 | P9: =Raw_Model!M9 | Q9: =Marginal_Model!M9 | R9: =IF(P9="","",EXP(-(Inputs!$B$7*Raw_Model!Q9+(1-Inputs!$B$7)*Marginal_Model!Q9))) | S9: =IF(R9="","",-LN(R9))
A10: 1 | B10: =Inputs!$B$5 -> 4 | C10: 11 | D10: =Raw_Model!G10 -> 1.5932296e-08 | E10: =Marginal_Model!J10 -> 1.5932296e-08 | F10: =EXP(-(Inputs!$B$7*Raw_Model!N10+(1-Inputs!$B$7)*Marginal_Model!N10)) -> 1.5932296e-08 | G10: =-LN(F10) -> 17.954918 | H10: =Raw_Model!I10 -> 6.1194959e-05 | I10: =Marginal_Model!K10 -> 2.3547844e-09 | J10: =EXP(-(Inputs!$B$7*Raw_Model!O10+(1-Inputs!$B$7)*Marginal_Model!O10)) -> 8.0124023e-06 | K10: =-LN(J10) -> 11.73452 | L10: =Raw_Model!K10 -> 5.836006e-11 | M10: =Marginal_Model!L10 -> 2.2456974e-15 | N10: =EXP(-(Inputs!$B$7*Raw_Model!P10+(1-Inputs!$B$7)*Marginal_Model!P10)) -> 7.6412223e-12 | O10: =-LN(N10) -> 25.597464 | P10: =Raw_Model!M10 | Q10: =Marginal_Model!M10 | R10: =IF(P10="","",EXP(-(Inputs!$B$7*Raw_Model!Q10+(1-Inputs!$B$7)*Marginal_Model!Q10))) | S10: =IF(R10="","",-LN(R10))
A11: 1 | B11: =Inputs!$B$5 -> 4 | C11: 12 | D11: =Raw_Model!G11 -> 1.3005956e-09 | E11: =Marginal_Model!J11 -> 1.3005956e-09 | F11: =EXP(-(Inputs!$B$7*Raw_Model!N11+(1-Inputs!$B$7)*Marginal_Model!N11)) -> 1.3005956e-09 | G11: =-LN(F11) -> 20.460443 | H11: =Raw_Model!I11 -> 4.7956866e-05 | I11: =Marginal_Model!K11 -> 3.0756367e-10 | J11: =EXP(-(Inputs!$B$7*Raw_Model!O11+(1-Inputs!$B$7)*Marginal_Model!O11)) -> 4.3880103e-06 | K11: =-LN(J11) -> 12.336635 | L11: =Raw_Model!K11 -> 1.1433808e-11 | M11: =Marginal_Model!L11 -> 7.3328894e-17 | N11: =EXP(-(Inputs!$B$7*Raw_Model!P11+(1-Inputs!$B$7)*Marginal_Model!P11)) -> 1.0461832e-12 | O11: =-LN(N11) -> 27.585873 | P11: =Raw_Model!M11 | Q11: =Marginal_Model!M11 | R11: =IF(P11="","",EXP(-(Inputs!$B$7*Raw_Model!Q11+(1-Inputs!$B$7)*Marginal_Model!Q11))) | S11: =IF(R11="","",-LN(R11))
A12: 1 | B12: =Inputs!$B$5 -> 4 | C12: 13 | D12: =Raw_Model!G12 -> 8.1287227e-11 | E12: =Marginal_Model!J12 -> 8.1287227e-11 | F12: =EXP(-(Inputs!$B$7*Raw_Model!N12+(1-Inputs!$B$7)*Marginal_Model!N12)) -> 8.1287227e-11 | G12: =-LN(F12) -> 23.233032 | H12: =Raw_Model!I12 -> 3.8964953e-05 | I12: =Marginal_Model!K12 -> 3.8445459e-11 | J12: =EXP(-(Inputs!$B$7*Raw_Model!O12+(1-Inputs!$B$7)*Marginal_Model!O12)) -> 2.4519315e-06 | K12: =-LN(J12) -> 12.918634 | L12: =Raw_Model!K12 -> 2.3224922e-12 | M12: =Marginal_Model!L12 -> 2.2915279e-18 | N12: =EXP(-(Inputs!$B$7*Raw_Model!P12+(1-Inputs!$B$7)*Marginal_Model!P12)) -> 1.4614651e-13 | O12: =-LN(N12) -> 29.554167 | P12: =Raw_Model!M12 | Q12: =Marginal_Model!M12 | R12: =IF(P12="","",EXP(-(Inputs!$B$7*Raw_Model!Q12+(1-Inputs!$B$7)*Marginal_Model!Q12))) | S12: =IF(R12="","",-LN(R12))
A13: 1 | B13: =Inputs!$B$5 -> 4 | C13: 14 | D13: =Raw_Model!G13 -> 3.4590309e-12 | E13: =Marginal_Model!J13 -> 3.4590309e-12 | F13: =EXP(-(Inputs!$B$7*Raw_Model!N13+(1-Inputs!$B$7)*Marginal_Model!N13)) -> 3.4590309e-12 | G13: =-LN(F13) -> 26.390033 | H13: =Raw_Model!I13 -> 3.0950885e-05 | I13: =Marginal_Model!K13 -> 4.3626053e-12 | J13: =EXP(-(Inputs!$B$7*Raw_Model!O13+(1-Inputs!$B$7)*Marginal_Model!O13)) -> 1.3197378e-06 | K13: =-LN(J13) -> 13.538078 | L13: =Raw_Model!K13 -> 4.6120412e-13 | M13: =Marginal_Model!L13 -> 6.5007884e-20 | N13: =EXP(-(Inputs!$B$7*Raw_Model!P13+(1-Inputs!$B$7)*Marginal_Model!P13)) -> 1.9665625e-14 | O13: =-LN(N13) -> 31.559904 | P13: =Raw_Model!M13 | Q13: =Marginal_Model!M13 | R13: =IF(P13="","",EXP(-(Inputs!$B$7*Raw_Model!Q13+(1-Inputs!$B$7)*Marginal_Model!Q13))) | S13: =IF(R13="","",-LN(R13))
A14: 1 | B14: =Inputs!$B$5 -> 4 | C14: 15 | D14: =Raw_Model!G14 -> 7.5196325e-14 | E14: =Marginal_Model!J14 -> 7.5196325e-14 | F14: =EXP(-(Inputs!$B$7*Raw_Model!N14+(1-Inputs!$B$7)*Marginal_Model!N14)) -> 7.5196325e-14 | G14: =-LN(F14) -> 30.218674 | H14: =Raw_Model!I14 -> 2.018536e-05 | I14: =Marginal_Model!K14 -> 3.7935698e-13 | J14: =EXP(-(Inputs!$B$7*Raw_Model!O14+(1-Inputs!$B$7)*Marginal_Model!O14)) -> 5.752264e-07 | K14: =-LN(J14) -> 14.368502 | L14: =Raw_Model!K14 -> 7.5196325e-14 | M14: =Marginal_Model!L14 -> 1.4132149e-21 | N14: =EXP(-(Inputs!$B$7*Raw_Model!P14+(1-Inputs!$B$7)*Marginal_Model!P14)) -> 2.1428853e-15 | O14: =-LN(N14) -> 33.776623 | P14: =Raw_Model!M14 | Q14: =Marginal_Model!M14 | R14: =IF(P14="","",EXP(-(Inputs!$B$7*Raw_Model!Q14+(1-Inputs!$B$7)*Marginal_Model!Q14))) | S14: =IF(R14="","",-LN(R14))
A15: 2 | B15: =Inputs!$B$6 -> 5 | C15: 3 | D15: =Raw_Model!G15 -> 0.033691225 | E15: =Marginal_Model!J15 -> 0.033691225 | F15: =EXP(-(Inputs!$B$7*Raw_Model!N15+(1-Inputs!$B$7)*Marginal_Model!N15)) -> 0.033691225 | G15: =-LN(F15) -> 3.3905178 | H15: =Raw_Model!I15 -> 0.024065161 | I15: =Marginal_Model!K15 -> 0.024065161 | J15: =EXP(-(Inputs!$B$7*Raw_Model!O15+(1-Inputs!$B$7)*Marginal_Model!O15)) -> 0.024065161 | K15: =-LN(J15) -> 3.7269901 | L15: =Raw_Model!K15 -> 0.00096260644 | M15: =Marginal_Model!L15 -> 0.00096260644 | N15: =EXP(-(Inputs!$B$7*Raw_Model!P15+(1-Inputs!$B$7)*Marginal_Model!P15)) -> 0.00096260644 | O15: =-LN(N15) -> 6.9458659 | P15: =Raw_Model!M15 -> 0.0022213995 | Q15: =Marginal_Model!M15 -> 0.0022213995 | R15: =IF(P15="","",EXP(-(Inputs!$B$7*Raw_Model!Q15+(1-Inputs!$B$7)*Marginal_Model!Q15))) -> 0.0022213995 | S15: =IF(R15="","",-LN(R15)) -> 6.1096179
A16: 2 | B16: =Inputs!$B$6 -> 5 | C16: 4 | D16: =Raw_Model!G16 -> 0.0056152042 | E16: =Marginal_Model!J16 -> 0.0056152042 | F16: =EXP(-(Inputs!$B$7*Raw_Model!N16+(1-Inputs!$B$7)*Marginal_Model!N16)) -> 0.0056152042 | G16: =-LN(F16) -> 5.1822773 | H16: =Raw_Model!I16 -> 0.0061705541 | I16: =Marginal_Model!K16 -> 0.0030852771 | J16: =EXP(-(Inputs!$B$7*Raw_Model!O16+(1-Inputs!$B$7)*Marginal_Model!O16)) -> 0.0053717794 | K16: =-LN(J16) -> 5.2265961 | L16: =Raw_Model!K16 -> 4.9364433e-05 | M16: =Marginal_Model!L16 -> 2.4682216e-05 | N16: =EXP(-(Inputs!$B$7*Raw_Model!P16+(1-Inputs!$B$7)*Marginal_Model!P16)) -> 4.2974235e-05 | O16: =-LN(N16) -> 10.05491 | P16: =Raw_Model!M16 -> 6.1705541e-05 | Q16: =Marginal_Model!M16 -> 6.1705541e-05 | R16: =IF(P16="","",EXP(-(Inputs!$B$7*Raw_Model!Q16+(1-Inputs!$B$7)*Marginal_Model!Q16))) -> 6.1705541e-05 | S16: =IF(R16="","",-LN(R16)) -> 9.6931368
A17: 2 | B17: =Inputs!$B$6 -> 5 | C17: 5 | D17: =Raw_Model!G17 -> 0.00086996122 | E17: =Marginal_Model!J17 -> 0.00086996122 | F17: =EXP(-(Inputs!$B$7*Raw_Model!N17+(1-Inputs!$B$7)*Marginal_Model!N17)) -> 0.00086996122 | G17: =-LN(F17) -> 7.0470619 | H17: =Raw_Model!I17 -> 0.0019916695 | I17: =Marginal_Model!K17 -> 0.00039833389 | J17: =EXP(-(Inputs!$B$7*Raw_Model!O17+(1-Inputs!$B$7)*Marginal_Model!O17)) -> 0.0014435215 | K17: =-LN(J17) -> 6.5406696 | L17: =Raw_Model!K17 -> 3.1866711e-06 | M17: =Marginal_Model!L17 -> 6.3733423e-07 | N17: =EXP(-(Inputs!$B$7*Raw_Model!P17+(1-Inputs!$B$7)*Marginal_Model!P17)) -> 2.3096344e-06 | O17: =-LN(N17) -> 12.978421 | P17: =Raw_Model!M17 -> 8.6909213e-07 | Q17: =Marginal_Model!M17 -> 8.6909213e-07 | R17: =IF(P17="","",EXP(-(Inputs!$B$7*Raw_Model!Q17+(1-Inputs!$B$7)*Marginal_Model!Q17))) -> 8.6909213e-07 | S17: =IF(R17="","",-LN(R17)) -> 13.955817
A18: 2 | B18: =Inputs!$B$6 -> 5 | C18: 6 | D18: =Raw_Model!G18 -> 0.00012428017 | E18: =Marginal_Model!J18 -> 0.00012428017 | F18: =EXP(-(Inputs!$B$7*Raw_Model!N18+(1-Inputs!$B$7)*Marginal_Model!N18)) -> 0.00012428017 | G18: =-LN(F18) -> 8.9929721 | H18: =Raw_Model!I18 -> 0.00077597512 | I18: =Marginal_Model!K18 -> 5.1731674e-05 | J18: =EXP(-(Inputs!$B$7*Raw_Model!O18+(1-Inputs!$B$7)*Marginal_Model!O18)) -> 0.00045147067 | K18: =-LN(J18) -> 7.7030001 | L18: =Raw_Model!K18 -> 2.4831204e-07 | M18: =Marginal_Model!L18 -> 1.6554136e-08 | N18: =EXP(-(Inputs!$B$7*Raw_Model!P18+(1-Inputs!$B$7)*Marginal_Model!P18)) -> 1.4447061e-07 | O18: =-LN(N18) -> 15.75019 | P18: =Raw_Model!M18 | Q18: =Marginal_Model!M18 | R18: =IF(P18="","",EXP(-(Inputs!$B$7*Raw_Model!Q18+(1-Inputs!$B$7)*Marginal_Model!Q18))) | S18: =IF(R18="","",-LN(R18))
A19: 2 | B19: =Inputs!$B$6 -> 5 | C19: 7 | D19: =Raw_Model!G19 -> 1.6210458e-05 | E19: =Marginal_Model!J19 -> 1.6210458e-05 | F19: =EXP(-(Inputs!$B$7*Raw_Model!N19+(1-Inputs!$B$7)*Marginal_Model!N19)) -> 1.6210458e-05 | G19: =-LN(F19) -> 11.029854 | H19: =Raw_Model!I19 -> 0.00035424951 | I19: =Marginal_Model!K19 -> 6.7476097e-06 | J19: =EXP(-(Inputs!$B$7*Raw_Model!O19+(1-Inputs!$B$7)*Marginal_Model!O19)) -> 0.00016042698 | K19: =-LN(J19) -> 8.7376717 | L19: =Raw_Model!K19 -> 2.2671969e-08 | M19: =Marginal_Model!L19 -> 4.3184702e-10 | N19: =EXP(-(Inputs!$B$7*Raw_Model!P19+(1-Inputs!$B$7)*Marginal_Model!P19)) -> 1.0267326e-08 | O19: =-LN(N19) -> 18.394299 | P19: =Raw_Model!M19 | Q19: =Marginal_Model!M19 | R19: =IF(P19="","",EXP(-(Inputs!$B$7*Raw_Model!Q19+(1-Inputs!$B$7)*Marginal_Model!Q19))) | S19: =IF(R19="","",-LN(R19))
A20: 2 | B20: =Inputs!$B$6 -> 5 | C20: 8 | D20: =Raw_Model!G20 -> 1.9071127e-06 | E20: =Marginal_Model!J20 -> 1.9071127e-06 | F20: =EXP(-(Inputs!$B$7*Raw_Model!N20+(1-Inputs!$B$7)*Marginal_Model!N20)) -> 1.9071127e-06 | G20: =-LN(F20) -> 13.16992 | H20: =Raw_Model!I20 -> 0.0001852285 | I20: =Marginal_Model!K20 -> 8.8204048e-07 | J20: =EXP(-(Inputs!$B$7*Raw_Model!O20+(1-Inputs!$B$7)*Marginal_Model!O20)) -> 6.3571719e-05 | K20: =-LN(J20) -> 9.6633419 | L20: =Raw_Model!K20 -> 2.3709248e-09 | M20: =Marginal_Model!L20 -> 1.1290118e-11 | N20: =EXP(-(Inputs!$B$7*Raw_Model!P20+(1-Inputs!$B$7)*Marginal_Model!P20)) -> 8.13718e-10 | O20: =-LN(N20) -> 20.929407 | P20: =Raw_Model!M20 | Q20: =Marginal_Model!M20 | R20: =IF(P20="","",EXP(-(Inputs!$B$7*Raw_Model!Q20+(1-Inputs!$B$7)*Marginal_Model!Q20))) | S20: =IF(R20="","",-LN(R20))
A21: 2 | B21: =Inputs!$B$6 -> 5 | C21: 9 | D21: =Raw_Model!G21 -> 1.9925058e-07 | E21: =Marginal_Model!J21 -> 1.9925058e-07 | F21: =EXP(-(Inputs!$B$7*Raw_Model!N21+(1-Inputs!$B$7)*Marginal_Model!N21)) -> 1.9925058e-07 | G21: =-LN(F21) -> 15.428703 | H21: =Raw_Model!I21 -> 0.0001088563 | I21: =Marginal_Model!K21 -> 1.1519185e-07 | J21: =EXP(-(Inputs!$B$7*Raw_Model!O21+(1-Inputs!$B$7)*Marginal_Model!O21)) -> 2.7654589e-05 | K21: =-LN(J21) -> 10.495719 | L21: =Raw_Model!K21 -> 2.7867213e-10 | M21: =Marginal_Model!L21 -> 2.9489115e-13 | N21: =EXP(-(Inputs!$B$7*Raw_Model!P21+(1-Inputs!$B$7)*Marginal_Model!P21)) -> 7.0795749e-11 | O21: =-LN(N21) -> 23.371222 | P21: =Raw_Model!M21 | Q21: =Marginal_Model!M21 | R21: =IF(P21="","",EXP(-(Inputs!$B$7*Raw_Model!Q21+(1-Inputs!$B$7)*Marginal_Model!Q21))) | S21: =IF(R21="","",-LN(R21))
A22: 2 | B22: =Inputs!$B$6 -> 5 | C22: 10 | D22: =Raw_Model!G22 -> 1.8113689e-08 | E22: =Marginal_Model!J22 -> 1.8113689e-08 | F22: =EXP(-(Inputs!$B$7*Raw_Model!N22+(1-Inputs!$B$7)*Marginal_Model!N22)) -> 1.8113689e-08 | G22: =-LN(F22) -> 17.826598 | H22: =Raw_Model!I22 -> 7.0685911e-05 | I22: =Marginal_Model!K22 -> 1.4959981e-08 | J22: =EXP(-(Inputs!$B$7*Raw_Model!O22+(1-Inputs!$B$7)*Marginal_Model!O22)) -> 1.3015249e-05 | K22: =-LN(J22) -> 11.249389 | L22: =Raw_Model!K22 -> 3.6191186e-11 | M22: =Marginal_Model!L22 -> 7.6595103e-15 | N22: =EXP(-(Inputs!$B$7*Raw_Model!P22+(1-Inputs!$B$7)*Marginal_Model!P22)) -> 6.6638077e-12 | O22: =-LN(N22) -> 25.73433 | P22: =Raw_Model!M22 | Q22: =Marginal_Model!M22 | R22: =IF(P22="","",EXP(-(Inputs!$B$7*Raw_Model!Q22+(1-Inputs!$B$7)*Marginal_Model!Q22))) | S22: =IF(R22="","",-LN(R22))
A23: 2 | B23: =Inputs!$B$6 -> 5 | C23: 11 | D23: =Raw_Model!G23 -> 1.3933607e-09 | E23: =Marginal_Model!J23 -> 1.3933607e-09 | F23: =EXP(-(Inputs!$B$7*Raw_Model!N23+(1-Inputs!$B$7)*Marginal_Model!N23)) -> 1.3933607e-09 | G23: =-LN(F23) -> 20.391547 | H23: =Raw_Model!I23 -> 4.9842629e-05 | I23: =Marginal_Model!K23 -> 1.9179463e-09 | J23: =EXP(-(Inputs!$B$7*Raw_Model!O23+(1-Inputs!$B$7)*Marginal_Model!O23)) -> 6.5260146e-06 | K23: =-LN(J23) -> 11.939714 | L23: =Raw_Model!K23 -> 5.1038852e-12 | M23: =Marginal_Model!L23 -> 1.963977e-16 | N23: =EXP(-(Inputs!$B$7*Raw_Model!P23+(1-Inputs!$B$7)*Marginal_Model!P23)) -> 6.682639e-13 | O23: =-LN(N23) -> 28.034093 | P23: =Raw_Model!M23 | Q23: =Marginal_Model!M23 | R23: =IF(P23="","",EXP(-(Inputs!$B$7*Raw_Model!Q23+(1-Inputs!$B$7)*Marginal_Model!Q23))) | S23: =IF(R23="","",-LN(R23))
A24: 2 | B24: =Inputs!$B$6 -> 5 | C24: 12 | D24: =Raw_Model!G24 -> 8.7085042e-11 | E24: =Marginal_Model!J24 -> 8.7085042e-11 | F24: =EXP(-(Inputs!$B$7*Raw_Model!N24+(1-Inputs!$B$7)*Marginal_Model!N24)) -> 8.7085042e-11 | G24: =-LN(F24) -> 23.164136 | H24: =Raw_Model!I24 -> 3.7381972e-05 | I24: =Marginal_Model!K24 -> 2.3974329e-10 | J24: =EXP(-(Inputs!$B$7*Raw_Model!O24+(1-Inputs!$B$7)*Marginal_Model!O24)) -> 3.420417e-06 | K24: =-LN(J24) -> 12.585748 | L24: =Raw_Model!K24 -> 7.6558278e-13 | M24: =Marginal_Model!L24 -> 4.9099425e-18 | N24: =EXP(-(Inputs!$B$7*Raw_Model!P24+(1-Inputs!$B$7)*Marginal_Model!P24)) -> 7.005014e-14 | O24: =-LN(N24) -> 30.289565 | P24: =Raw_Model!M24 | Q24: =Marginal_Model!M24 | R24: =IF(P24="","",EXP(-(Inputs!$B$7*Raw_Model!Q24+(1-Inputs!$B$7)*Marginal_Model!Q24))) | S24: =IF(R24="","",-LN(R24))
